Workbook

Sheet Summary
A1: Summary — 318 applicants
A3: Grade applied | B3: Applicants | C3: Share
A4: PreKG - Express Interest Now | B4: =COUNTIF('Applicant Insights'!$C$6:$C$350,"PreKG - Express Interest Now") -> 36 | C4: =IFERROR(B4/318,0) -> 0.11320755
A5: PreKG | B5: =COUNTIF('Applicant Insights'!$C$6:$C$350,"PreKG") -> 1 | C5: =IFERROR(B5/318,0) -> 0.0031446541
A6: LKG | B6: =COUNTIF('Applicant Insights'!$C$6:$C$350,"LKG") -> 40 | C6: =IFERROR(B6/318,0) -> 0.12578616
A7: UKG | B7: =COUNTIF('Applicant Insights'!$C$6:$C$350,"UKG") -> 21 | C7: =IFERROR(B7/318,0) -> 0.066037736
A8: Grade 1 | B8: =COUNTIF('Applicant Insights'!$C$6:$C$350,"Grade 1") -> 43 | C8: =IFERROR(B8/318,0) -> 0.13522013
A9: Grade 2 | B9: =COUNTIF('Applicant Insights'!$C$6:$C$350,"Grade 2") -> 22 | C9: =IFERROR(B9/318,0) -> 0.06918239
A10: Grade 3 | B10: =COUNTIF('Applicant Insights'!$C$6:$C$350,"Grade 3") -> 22 | C10: =IFERROR(B10/318,0) -> 0.06918239
A11: Grade 4 | B11: =COUNTIF('Applicant Insights'!$C$6:$C$350,"Grade 4") -> 27 | C11: =IFERROR(B11/318,0) -> 0.08490566
A12: Grade 5 | B12: =COUNTIF('Applicant Insights'!$C$6:$C$350,"Grade 5") -> 29 | C12: =IFERROR(B12/318,0) -> 0.091194969
A13: Grade 6 | B13: =COUNTIF('Applicant Insights'!$C$6:$C$350,"Grade 6") -> 19 | C13: =IFERROR(B13/318,0) -> 0.059748428
A14: Grade 7 | B14: =COUNTIF('Applicant Insights'!$C$6:$C$350,"Grade 7") -> 15 | C14: =IFERROR(B14/318,0) -> 0.047169811
A15: Grade 8 | B15: =COUNTIF('Applicant Insights'!$C$6:$C$350,"Grade 8") -> 18 | C15: =IFERROR(B15/318,0) -> 0.056603774
A16: Grade 9 | B16: =COUNTIF('Applicant Insights'!$C$6:$C$350,"Grade 9") -> 2 | C16: =IFERROR(B16/318,0) -> 0.0062893082
A17: Grade 11 | B17: =COUNTIF('Applicant Insights'!$C$6:$C$350,"Grade 11") -> 23 | C17: =IFERROR(B17/318,0) -> 0.072327044
A19: Estimated family income | B19: Applicants | C19: Share
A20: Below ₹15 L | B20: =COUNTIF('Applicant Insights'!$I$6:$I$350,"Below ₹15 L") -> 17 | C20: =IFERROR(B20/318,0) -> 0.053459119
A21: ₹15–30 L | B21: =COUNTIF('Applicant Insights'!$I$6:$I$350,"₹15–30 L") -> 34 | C21: =IFERROR(B21/318,0) -> 0.10691824
A22: ₹30–50 L | B22: =COUNTIF('Applicant Insights'!$I$6:$I$350,"₹30–50 L") -> 87 | C22: =IFERROR(B22/318,0) -> 0.27358491
A23: ₹50–80 L | B23: =COUNTIF('Applicant Insights'!$I$6:$I$350,"₹50–80 L") -> 83 | C23: =IFERROR(B23/318,0) -> 0.26100629
A24: ₹80 L and above | B24: =COUNTIF('Applicant Insights'!$I$6:$I$350,"₹80 L and above") -> 38 | C24: =IFERROR(B24/318,0) -> 0.11949686
A25: Not determinable | B25: =COUNTIF('Applicant Insights'!$I$6:$I$350,"Not determinable") -> 59 | C25: =IFERROR(B25/318,0) -> 0.18553459
A27: Proximity grade | B27: Applicants | C27: Share
A28: A — Doorstep (≤5 km) | B28: =COUNTIF('Applicant Insights'!$Q$6:$Q$350,"A — Doorstep (≤5 km)") -> 99 | C28: =IFERROR(B28/318,0) -> 0.31132075
A29: B — Near (5–10 km) | B29: =COUNTIF('Applicant Insights'!$Q$6:$Q$350,"B — Near (5–10 km)") -> 84 | C29: =IFERROR(B29/318,0) -> 0.26415094
A30: C — Commutable (10–15 km) | B30: =COUNTIF('Applicant Insights'!$Q$6:$Q$350,"C — Commutable (10–15 km)") -> 34 | C30: =IFERROR(B30/318,0) -> 0.10691824
A31: D — Far (15–25 km) | B31: =COUNTIF('Applicant Insights'!$Q$6:$Q$350,"D — Far (15–25 km)") -> 3 | C31: =IFERROR(B31/318,0) -> 0.0094339623
A32: E — Outside catchment (>25 km) | B32: =COUNTIF('Applicant Insights'!$Q$6:$Q$350,"E — Outside catchment (>25 km)") -> 7 | C32: =IFERROR(B32/318,0) -> 0.022012579
A33: U — Not determinable | B33: =COUNTIF('Applicant Insights'!$Q$6:$Q$350,"U — Not determinable") -> 91 | C33: =IFERROR(B33/318,0) -> 0.28616352
A35: Transfer out of Chennai | B35: Applicants | C35: Share
A36: High | B36: =COUNTIF('Applicant Insights'!$L$6:$L$350,"High") -> 24 | C36: =IFERROR(B36/318,0) -> 0.075471698
A37: Medium | B37: =COUNTIF('Applicant Insights'!$L$6:$L$350,"Medium") -> 95 | C37: =IFERROR(B37/318,0) -> 0.29874214
A38: Low | B38: =COUNTIF('Applicant Insights'!$L$6:$L$350,"Low") -> 199 | C38: =IFERROR(B38/318,0) -> 0.62578616
A40: Transfer out of India | B40: Applicants | C40: Share
A41: High | B41: =COUNTIF('Applicant Insights'!$M$6:$M$350,"High") -> 15 | C41: =IFERROR(B41/318,0) -> 0.047169811
A42: Medium | B42: =COUNTIF('Applicant Insights'!$M$6:$M$350,"Medium") -> 88 | C42: =IFERROR(B42/318,0) -> 0.27672956
A43: Low | B43: =COUNTIF('Applicant Insights'!$M$6:$M$350,"Low") -> 215 | C43: =IFERROR(B43/318,0) -> 0.67610063
A45: Profession 1 (father) | B45: Parents | C45: Share
A46: Homemaker | B46: =COUNTIF('Applicant Insights'!$G$6:$G$350,"Homemaker") -> 0 | C46: =IFERROR(B46/318,0) -> 0
...

Sheet Applicant Insights
A1: HLC International — Applicant Insights, AY 2026–27 cycle
A2: Internal and confidential. Income, mobility and distance are estimates from proxies — see the Method tab. Contact details deliberately excluded.
A4: APPLICANT | E4: FAMILY PROFILE | I4: ESTIMATED INCOME | L4: MOBILITY | O4: PROXIMITY | T4: WHY HLC
A5: # | B5: Applicant | C5: Grade applied | D5: Application date | E5: Father — occupation · role · employer | F5: Mother — occupation · role · employer | G5: Profession 1 (father) | H5: Profession 2 (mother) | I5: Family income band | J5: Range (₹ lakh a year) | K5: Confidence | L5: Transfer out of Chennai | M5: Transfer out of India | N5: Relocation note | O5: Locality | P5: Est. distance (km) | Q5: Proximity grade | R5: HLC families in same community | S5: HLC students in same locality | T5: Primary reason | U5: All reasons | V5: In their words
A6: PreKG - Express Interest Now · 36 applicants
A7: 1 | B7: R.Daanya | C7: PreKG - Express Interest Now | D7: 2025-11-01 | E7: — | F7: — | G7: Not stated | H7: Not stated | I7: Not determinable | J7: — | K7: — | L7: Low | M7: Low | O7: Not clear | P7: — | Q7: U — Not determinable | R7: 0 | S7: 0 | T7: Not stated / general | U7: Not stated / general
A8: 2 | B8: Srishti S. | C8: PreKG - Express Interest Now | D8: 2025-11-01 | E8: — | F8: — | G8: Not stated | H8: Not stated | I8: Not determinable | J8: — | K8: — | L8: Low | M8: Low | O8: Not clear | P8: — | Q8: U — Not determinable | R8: 0 | S8: 0 | T8: Not stated / general | U8: Not stated / general
A9: 3 | B9: KANISHA | C9: PreKG - Express Interest Now | D9: 2025-11-01 | E9: — | F9: — | G9: Not stated | H9: Not stated | I9: Not determinable | J9: — | K9: — | L9: Low | M9: Low | O9: Not clear | P9: — | Q9: U — Not determinable | R9: 0 | S9: 0 | T9: Not stated / general | U9: Not stated / general
A10: 4 | B10: Yuktha Kishore | C10: PreKG - Express Interest Now | D10: 2025-11-01 | E10: — | F10: — | G10: Not stated | H10: Not stated | I10: Not determinable | J10: — | K10: — | L10: Low | M10: Low | O10: Not clear | P10: — | Q10: U — Not determinable | R10: 0 | S10: 0 | T10: Not stated / general | U10: Not stated / general
A11: 5 | B11: Nila.R | C11: PreKG - Express Interest Now | D11: 2025-11-01 | E11: — | F11: — | G11: Not stated | H11: Not stated | I11: Not determinable | J11: — | K11: — | L11: Low | M11: Low | O11: Not clear | P11: — | Q11: U — Not determinable | R11: 0 | S11: 0 | T11: Not stated / general | U11: Not stated / general
A12: 6 | B12: R.Nila | C12: PreKG - Express Interest Now | D12: 2025-11-01 | E12: — | F12: — | G12: Not stated | H12: Not stated | I12: Not determinable | J12: — | K12: — | L12: Low | M12: Low | O12: Not clear | P12: — | Q12: U — Not determinable | R12: 0 | S12: 0 | T12: Not stated / general | U12: Not stated / general
A13: 7 | B13: Dhriti Ram | C13: PreKG - Express Interest Now | D13: 2025-11-01 | E13: — | F13: — | G13: Not stated | H13: Not stated | I13: Not determinable | J13: — | K13: — | L13: Low | M13: Low | O13: Not clear | P13: — | Q13: U — Not determinable | R13: 0 | S13: 0 | T13: Not stated / general | U13: Not stated / general
A14: 8 | B14: Meenakshi Vijayalakshmi Kartik | C14: PreKG - Express Interest Now | D14: 2025-11-02 | E14: — | F14: — | G14: Not stated | H14: Not stated | I14: Not determinable | J14: — | K14: — | L14: Low | M14: Low | O14: Not clear | P14: — | Q14: U — Not determinable | R14: 0 | S14: 0 | T14: Not stated / general | U14: Not stated / general
A15: 9 | B15: Rhythm | C15: PreKG - Express Interest Now | D15: 2025-11-03 | E15: — | F15: — | G15: Not stated | H15: Not stated | I15: Not determinable | J15: — | K15: — | L15: Low | M15: Low | O15: Not clear | P15: — | Q15: U — Not determinable | R15: 0 | S15: 0 | T15: Not stated / general | U15: Not stated / general
A16: 10 | B16: Iniya Madhavan | C16: PreKG - Express Interest Now | D16: 2025-11-03 | E16: — | F16: — | G16: Not stated | H16: Not stated | I16: Not determinable | J16: — | K16: — | L16: Low | M16: Low | O16: Not clear | P16: — | Q16: U — Not determinable | R16: 0 | S16: 0 | T16: Not stated / general | U16: Not stated / general
A17: 11 | B17: N.Nia Nithwin | C17: PreKG - Express Interest Now | D17: 2025-11-03 | E17: — | F17: — | G17: Not stated | H17: Not stated | I17: Not determinable | J17: — | K17: — | L17: Low | M17: Low | O17: Not clear | P17: — | Q17: U — Not determinable | R17: 0 | S17: 0 | T17: Not stated / general | U17: Not stated / general
A18: 12 | B18: Arshad Siddique | C18: PreKG - Express Interest Now | D18: 2025-11-03 | E18: Software engineer · Associate Vice President · Softeon | F18: Software engineer · Technical lead · Tata consultancy services | G18: IT and software | H18: IT and software | I18: ₹80 L and above | J18: 68–135 | K18: Medium | L18: Medium | M18: Medium | O18: Thalambur | P18: 3 | Q18: A — Doorstep (≤5 km) | R18: 3 (Casagrande Pavilion) | S18: 37 | T18: Child-centric, individual attention | U18: Child-centric, individual attention, Stress-free, joyful learning, Experiential, hands-on learning, Values, nurturing environment and inclusion, Life skills, confidence, leadership, Quality and standards of education, Interest and passion-led learning | V18: I’m choosing HLC because it offers a child-centred, experiential approach to education. I appreciate that HLC focuses on developing life skills, critical thinki…
A19: 13 | B19: Shawn Marcello S | C19: PreKG - Express Interest Now | D19: 2025-11-04 | E19: — | F19: — | G19: Not stated | H19: Not stated | I19: Not determinable | J19: — | K19: — | L19: Low | M19: Low | O19: Not clear | P19: — | Q19: U — Not determinable | R19: 0 | S19: 0 | T19: Not stated / general | U19: Not stated / general
A20: 14 | B20: Dheekshitha Dhivakar | C20: PreKG - Express Interest Now | D20: 2025-11-05 | E20: — | F20: — | G20: Not stated | H20: Not stated | I20: Not determinable | J20: — | K20: — | L20: Low | M20: Low | O20: Not clear | P20: — | Q20: U — Not determinable | R20: 0 | S20: 0 | T20: Not stated / general | U20: Not stated / general
A21: 15 | B21: Gayan Dev S | C21: PreKG - Express Interest Now | D21: 2025-11-05 | E21: — | F21: — | G21: Not stated | H21: Not stated | I21: Not determinable | J21: — | K21: — | L21: Low | M21: Low | O21: Not clear | P21: — | Q21: U — Not determinable | R21: 0 | S21: 0 | T21: Not stated / general | U21: Not stated / general
A22: 16 | B22: KRISHAV | C22: PreKG - Express Interest Now | D22: 2025-11-07 | E22: — | F22: — | G22: Not stated | H22: Not stated | I22: Not determinable | J22: — | K22: — | L22: Low | M22: Low | O22: Not clear | P22: — | Q22: U — Not determinable | R22: 0 | S22: 0 | T22: Not stated / general | U22: Not stated / general
A23: 17 | B23: Adhira A | C23: PreKG - Express Interest Now | D23: 2025-11-08 | E23: — | F23: — | G23: Not stated | H23: Not stated | I23: Not determinable | J23: — | K23: — | L23: Low | M23: Low | O23: Not clear | P23: — | Q23: U — Not determinable | R23: 0 | S23: 0 | T23: Not stated / general | U23: Not stated / general
A24: 18 | B24: Vanshika | C24: PreKG - Express Interest Now | D24: 2025-11-09 | E24: — | F24: — | G24: Not stated | H24: Not stated | I24: Not determinable | J24: — | K24: — | L24: Low | M24: Low | O24: Not clear | P24: — | Q24: U — Not determinable | R24: 0 | S24: 0 | T24: Not stated / general | U24: Not stated / general
A25: 19 | B25: karthikeyan B | C25: PreKG - Express Interest Now | D25: 2025-11-11 | E25: — | F25: — | G25: Not stated | H25: Not stated | I25: Not determinable | J25: — | K25: — | L25: Low | M25: Low | O25: Not clear | P25: — | Q25: U — Not determinable | R25: 0 | S25: 0 | T25: Not stated / general | U25: Not stated / general
A26: 20 | B26: K.S Aruvi | C26: PreKG - Express Interest Now | D26: 2025-11-11 | E26: — | F26: — | G26: Not stated | H26: Not stated | I26: Not determinable | J26: — | K26: — | L26: Low | M26: Low | O26: Not clear | P26: — | Q26: U — Not determinable | R26: 0 | S26: 0 | T26: Not stated / general | U26: Not stated / general
A27: 21 | B27: A.k.Mahat krishna | C27: PreKG - Express Interest Now | D27: 2025-11-13 | E27: Radiologist · Proprietor · Dr.anand's scan | F27: Home maker · Home maker · Home maker | G27: Healthcare | H27: Homemaker | I27: ₹30–50 L | J27: 20–50 | K27: Medium | L27: Low | M27: Low | O27: Karanai | P27: 1 | Q27: A — Doorstep (≤5 km) | R27: 14 (Jones Cassia) | S27: 13 | T27: Stress-free, joyful learning | U27: Stress-free, joyful learning | V27: Very happy with our first kid progress
A28: 22 | B28: Tharika V | C28: PreKG - Express Interest Now | D28: 2025-11-20 | E28: Supply Chain · Manager · Ford | F28: Career break · Previously worked as an HR operations lead · Not working currently | G28: Management and consulting | H28: Management and consulting | I28: ₹50–80 L | J28: 39–78 | K28: Medium | L28: Medium | M28: Medium | O28: Ottiyambakkam | P28: 11 | Q28: C — Commutable (10–15 km) | R28: 0 | S28: 9 | T28: Child-centric, individual attention | U28: Child-centric, individual attention, Stress-free, joyful learning, Experiential, hands-on learning, Values, nurturing environment and inclusion, Life skills, confidence, leadership, Interest and passion-led learning | V28: We are seeking HLC for our child because we believe in an environment that encourages curiosity, independence, and joyful learning. HLC’s philosophy of nurturin…
A29: 23 | B29: Aadhiran Jayaprathap | C29: PreKG - Express Interest Now | D29: 2025-11-25 | E29: — | F29: — | G29: Not stated | H29: Not stated | I29: Not determinable | J29: — | K29: — | L29: Low | M29: Low | O29: Not clear | P29: — | Q29: U — Not determinable | R29: 0 | S29: 0 | T29: Not stated / general | U29: Not stated / general
A30: 24 | B30: LASYA SHREE A | C30: PreKG - Express Interest Now | D30: 2025-11-25 | E30: — | F30: — | G30: Not stated | H30: Not stated | I30: Not determinable | J30: — | K30: — | L30: Low | M30: Low | O30: Not clear | P30: — | Q30: U — Not determinable | R30: 0 | S30: 0 | T30: Not stated / general | U30: Not stated / general
A31: 25 | B31: Adelina carlin | C31: PreKG - Express Interest Now | D31: 2025-11-25 | E31: — | F31: — | G31: Not stated | H31: Not stated | I31: Not determinable | J31: — | K31: — | L31: Low | M31: Low | O31: Not clear | P31: — | Q31: U — Not determinable | R31: 0 | S31: 0 | T31: Not stated / general | U31: Not stated / general
A32: 26 | B32: Hridhaan Shyam | C32: PreKG - Express Interest Now | D32: 2025-11-26 | E32: — | F32: — | G32: Not stated | H32: Not stated | I32: Not determinable | J32: — | K32: — | L32: Low | M32: Low | O32: Not clear | P32: — | Q32: U — Not determinable | R32: 0 | S32: 0 | T32: Not stated / general | U32: Not stated / general
A33: 27 | B33: Iyaan | C33: PreKG - Express Interest Now | D33: 2025-12-01 | E33: — | F33: — | G33: Not stated | H33: Not stated | I33: Not determinable | J33: — | K33: — | L33: Low | M33: Low | O33: Not clear | P33: — | Q33: U — Not determinable | R33: 0 | S33: 0 | T33: Not stated / general | U33: Not stated / general
A34: 28 | B34: Ayra Parry | C34: PreKG - Express Interest Now | D34: 2025-12-12 | E34: — | F34: — | G34: Not stated | H34: Not stated | I34: Not determinable | J34: — | K34: — | L34: Low | M34: Low | O34: Not clear | P34: — | Q34: U — Not determinable | R34: 0 | S34: 0 | T34: Not stated / general | U34: Not stated / general
A35: 29 | B35: Aadhiran.P.S | C35: PreKG - Express Interest Now | D35: 2025-12-18 | E35: — | F35: — | G35: Not stated | H35: Not stated | I35: Not determinable | J35: — | K35: — | L35: Low | M35: Low | O35: Not clear | P35: — | Q35: U — Not determinable | R35: 0 | S35: 0 | T35: Not stated / general | U35: Not stated / general
A36: 30 | B36: SAANVI V | C36: PreKG - Express Interest Now | D36: 2025-12-30 | E36: — | F36: — | G36: Not stated | H36: Not stated | I36: Not determinable | J36: — | K36: — | L36: Low | M36: Low | O36: Not clear | P36: — | Q36: U — Not determinable | R36: 0 | S36: 0 | T36: Not stated / general | U36: Not stated / general
A37: 31 | B37: Aaradhya Vignesh | C37: PreKG - Express Interest Now | D37: 2025-12-30 | E37: — | F37: — | G37: Not stated | H37: Not stated | I37: Not determinable | J37: — | K37: — | L37: Low | M37: Low | O37: Not clear | P37: — | Q37: U — Not determinable | R37: 0 | S37: 0 | T37: Not stated / general | U37: Not stated / general
A38: 32 | B38: Reehaa S Palani | C38: PreKG - Express Interest Now | D38: 2026-01-04 | E38: — | F38: — | G38: Not stated | H38: Not stated | I38: Not determinable | J38: — | K38: — | L38: Low | M38: Low | O38: Not clear | P38: — | Q38: U — Not determinable | R38: 0 | S38: 0 | T38: Not stated / general | U38: Not stated / general
A39: 33 | B39: Hamsika V | C39: PreKG - Express Interest Now | D39: 2026-01-09 | E39: — | F39: — | G39: Not stated | H39: Not stated | I39: Not determinable | J39: — | K39: — | L39: Low | M39: Low | O39: Not clear | P39: — | Q39: U — Not determinable | R39: 0 | S39: 0 | T39: Not stated / general | U39: Not stated / general
A40: 34 | B40: Thara | C40: PreKG - Express Interest Now | D40: 2026-01-10 | E40: — | F40: — | G40: Not stated | H40: Not stated | I40: Not determinable | J40: — | K40: — | L40: Low | M40: Low | O40: Not clear | P40: — | Q40: U — Not determinable | R40: 0 | S40: 0 | T40: Not stated / general | U40: Not stated / general
... A42: 36 | B42: Vedh Nandan | C42: PreKG - Express Interest Now | D42: 2026-01-13 | E42: — | F42: — | G42: Not stated | H42: Not stated | I42: Not determinable | J42: — | K42: — | L42: Low | M42: Low | O42: Not clear | P42: — | Q42: U — Not determinable | R42: 0 | S42: 0 | T42: Not stated / general | U42: Not stated / general
...

Sheet Method
A1: How the estimates were made — read before using
A2: Scope: the "just 2025-26" sheet of the application form (applications from November 2025), matched against the 2025-26 Master List of current students.
A3: Income: each parent's occupation and role are mapped to a salary range by seniority (for example CXO or Director ₹50–100 L; Manager or Lead ₹18–35 L; Engineer or Analyst ₹8–20 L; doctor ₹20–50 L; homemaker ₹0). Ranges rise about 20% for global MNC employers. Family range = father + mother. Confidence is Medium where a clear role or profession was stated, Low where only a generic label (for example "IT") was given. These are proxies, not facts.
A4: Profession 1 and 2: the father's and mother's occupation, role and employer standardised into twelve categories (for example IT and software, Banking and finance, Healthcare, Business owner, Homemaker). Where the occupation was vague, the employer decided it.
A5: Mobility: out-of-India likelihood is High where roles mention global, APAC, international or onsite work; Medium for global MNCs and IT-services managers; Low for business owners, doctors and local professions. Out-of-Chennai is High for defence, banking and government roles. Families mentioning relocation into Chennai are flagged separately.
A6: Distance: approximate road distance from HLC Karanai to the centre of the locality named in the address, or to the pincode area where no locality was found. No geocoding was used.
A7: Proximity grade: A Doorstep ≤5 km · B Near 5–10 km · C Commutable 10–15 km · D Far 15–25 km · E Outside catchment >25 km · U not determinable.
A8: Existing HLC families: an applicant is matched to current students whose address shares the same community or apartment name (a distinctive two-word name, or a rare word). Matches are probable, not certain.
A9: Why HLC: free-text answers were tagged against twelve themes by keywords. An answer can carry several themes; "Primary reason" is the first theme matched.
A10: Privacy: phone numbers, e-mails and parents' names are excluded. Income and mobility estimates are for internal planning only and must never be shared with families or used to treat applicants differently.
