Workbook

Sheet ReadMe
B2: AY 2027-28 Enrollment & Fund What-If Dashboard
B3: Built from your uploaded AY 27-28 financials. All figures in ₹ (INR).
B5: How to use
B6: 1. Go to the Inputs tab. Pick a scenario (Pessimistic / Realistic / Optimistic) in the yellow cell at the top — every other sheet updates instantly.
B7: 2. Every blue number on Inputs is editable — grade-wise new-joiner counts and their per-grade optimistic/pessimistic swing %, contribution % and its swing, fees, expenses, collection efficiency, cost variance, and fund balances.
B8: 3. The Dashboard tab shows the headline P&L, cash flow and fund position for whichever scenario is selected, plus a side-by-side comparison of all three scenarios and a chart.
B9: 4. The Calculations tab is the engine — grade-by-grade math for all three scenarios. You normally won't need to edit it; everything you'd want to change lives on Inputs.
B11: Key modelling choices
B12: - New Joiners are now Max Capacity x Capture %, not a blanket swing. The 'New Joiners' numbers in your source file are actually the school's MAXIMUM SEAT CAPACITY per grade (per your correction) — so Optimistic = filling 100% of that capacity, and Realistic / Pessimistic are each Capacity x a per-grade Capture % (how much of capacity you realistically expect to fill). A bigger capacity number is harder to fully realize (e.g. LKG, and especially AS/Grade 11) on top of AS being the structurally harder grade to convert — both are reflected in lower default Capture % for AS than for Grade I. Every Capture % is editable per grade.
B13: - Returnable Contribution % (existing students, to the corpus/building fund) also gets its own pessimistic/optimistic range per grade, as a +/- percentage-point swing on the realistic %.
B14: - Contributions from existing students, and (optionally) the Advance from new joiners, are treated as a REFUNDABLE LIABILITY — they hit Cash Inflow and the Fund roll-forward, but are excluded from P&L revenue. No interest is accrued on this balance, matching your note that contributions are returnable without interest.
B15: - Whether the Advance from new joiners is returnable or not is a Yes/No toggle on Inputs (default: Yes / returnable) since your brief only confirmed the treatment for existing-student contributions.
... B28: Yellow fill = key scenario / toggle controls

Sheet Inputs
B1: Inputs & Assumptions
B2: Edit any blue cell. Grades are rows, so each grade can have its own new-joiner / contribution swing (no blanket %).
B4: Active Scenario | C4: Realistic | E4: Treat 'Advance per New Joiner' as returnable (liability), not revenue? | J4: Yes
B6: Grade-wise enrollment, fee, contribution & dropout assumptions
B7: Grade | C7: Existing Students | D7: Base Fee (₹, LAST year's) | E7: Fee Increase % (applied to Base Fee) | F7: New Joiners - Max Capacity (= Optimistic) | G7: New Joiners Realistic Capture % (of Max Capacity) | H7: New Joiners Pessimistic Capture % (of Max Capacity) | I7: Contribution % - Realistic (existing students) | J7: Contribution Pessimistic Δ (pp) | K7: Contribution Optimistic Δ (pp) | L7: Contribution per Student (₹) | M7: Advance per New Joiner (₹) | N7: Possible Dropouts - Realistic (existing students) | O7: Dropout Pessimistic Δ% (more dropouts) | P7: Dropout Optimistic Δ% (fewer dropouts)
B8: Pre-KG | C8: 0 | F8: 0 | G8: 0.7 | H8: 0.5 | J8: 0 | K8: 0 | N8: 0 | O8: 0 | P8: 0
B9: LKG | C9: 4 | D9: 210000 | E9: 0 | F9: 26 | G9: 0.7 | H9: 0.5 | I9: 0 | J9: 0 | K9: 0 | M9: 100000 | N9: 0 | O9: 0 | P9: 0
B10: UKG | C10: 15 | D10: 201000 | E10: 0 | F10: 15 | G10: 0.75 | H10: 0.55 | I10: 0 | J10: 0 | K10: 0 | M10: 100000 | N10: 0 | O10: 0 | P10: 0
B11: I | C11: 23 | D11: 217000 | E11: 0 | F11: 14 | G11: 0.8 | H11: 0.6 | I11: 0 | J11: 0 | K11: 0 | M11: 100000 | N11: 0 | O11: 0 | P11: 0
B12: II | C12: 33 | D12: 217000 | E12: 0.2 | F12: 0 | G12: 0.7 | H12: 0.5 | I12: 0 | J12: 0 | K12: 0 | M12: 100000 | N12: 5 | O12: 0.5 | P12: -0.4
B13: III | C13: 34 | D13: 227000 | E13: 0.2 | F13: 0 | G13: 0.7 | H13: 0.5 | I13: 0 | J13: 0 | K13: 0 | M13: 100000 | N13: 5 | O13: 0.5 | P13: -0.4
B14: IV | C14: 32 | D14: 232000 | E14: 0.2 | F14: 0 | G14: 0.7 | H14: 0.5 | I14: 0 | J14: 0 | K14: 0 | M14: 100000 | N14: 5 | O14: 0.5 | P14: -0.4
B15: V | C15: 31 | D15: 254000 | E15: 0.2 | F15: 1 | G15: 0.7 | H15: 0.5 | I15: 0 | J15: 0 | K15: 0 | M15: 100000 | N15: 5 | O15: 0.5 | P15: -0.4
B16: VI | C16: 31 | D16: 270000 | E16: 0.2 | F16: 1 | G16: 0.7 | H16: 0.5 | I16: 0.2 | J16: -0.1 | K16: 0.1 | L16: 200000 | M16: 100000 | N16: 3 | O16: 0.5 | P16: -0.4
B17: VII | C17: 27 | D17: 288000 | E17: 0.2 | F17: 3 | G17: 0.7 | H17: 0.5 | I17: 0.2 | J17: -0.1 | K17: 0.1 | L17: 200000 | M17: 100000 | N17: 2 | O17: 0.5 | P17: -0.4
B18: VIII | C18: 25 | D18: 304000 | E18: 0.2 | F18: 5 | G18: 0.65 | H18: 0.45 | I18: 0.3 | J18: -0.1 | K18: 0.1 | L18: 200000 | M18: 100000 | N18: 2 | O18: 0.5 | P18: -0.4
B19: IX | C19: 26 | D19: 319000 | E19: 0.2 | F19: 4 | G19: 0.65 | H19: 0.45 | I19: 0.3 | J19: -0.1 | K19: 0.1 | L19: 200000 | M19: 100000 | N19: 1 | O19: 0.5 | P19: -0.4
B20: X | C20: 30 | D20: 332000 | E20: 0.2 | F20: 0 | G20: 0.7 | H20: 0.5 | I20: 0.2 | J20: -0.1 | K20: 0.1 | L20: 200000 | M20: 100000 | N20: 0 | O20: 0 | P20: 0
B21: AS | C21: 26 | D21: 294000 | E21: 0.2 | F21: 34 | G21: 0.5 | H21: 0.3 | I21: 0.1 | J21: -0.1 | K21: 0.1 | L21: 200000 | M21: 100000 | N21: 0 | O21: 0 | P21: 0
B22: A2 | C22: 29 | D22: 306000 | E22: 0.2 | F22: 1 | G22: 0.7 | H22: 0.5 | I22: 0 | J22: 0 | K22: 0 | M22: 100000 | N22: 0 | O22: 0 | P22: 0
B23: Total | C23: =SUM(C8:C22) -> 366 | F23: =SUM(F8:F22) -> 104 | N23: =SUM(N8:N22) -> 28
B25: Annual operating expenses (AY 2027-28 budget)
B26: Expense item | C26: Annual Amount (₹)
B27: Teacher salaries | C27: 57969300
B28: Rent | C28: 2750000
B29: Other core operating expenses | C29: 24347100
B30: Cambridge affiliation | C30: 1069196
B31: Safety / essential maintenance | C31: 2500000
B32: Property purchase loan servicing | C32: 13045454
B33: Growth marketing | C33: 5000000
B34: Additional / discretionary maintenance | C34: 2500000
B35: International obligations | C35: 4200000
B36: Miscellaneous Expenses | C36: =11338105/3 -> 3779368.3
B37: Total Operating Expenses | C37: =SUM(C27:C36) -> 1.1716042e+08
B39: Scenario overlays — overall dials
B40: The three Swing Multiplier columns are your single overall control per scenario: raise/lower one number here and every grade's New Joiner / Contribution / Dropout assumption (set on the table above) scales together, in proportion. 1.0 = the per-grade defaults above; 1.5 = 50% more aggressive; 0.5 = half as aggressive. NOTE the New Joiners multiplier is wired differently from the other two: New Joiners is now capacity-based (Optimistic = 100% of Max Capacity, fixed, so its multiplier cell is unused), and the multiplier instead scales the REALISTIC and PESSIMISTIC Capture % — i.e. Realistic's New Joiners multiplier IS active here, unlike Contribution/Dropout where Realistic is the fixed baseline and only Pessimistic/Optimistic scale. Cells with no effect for a given scenario are left white (not yellow) below. Fee Collection Efficiency % and Cost Variance % are a separate, cash/expense-only lever — they do NOT move New Joiners, Contribution % or Dropouts.
B41: Scenario | C41: Fee Collection Efficiency % (cash only) | D41: Cost Variance % (vs. budget) | E41: New Joiners Swing Multiplier (overall) | F41: Contribution Swing Multiplier (overall) | G41: Dropout Swing Multiplier (overall)
B42: Pessimistic | C42: 0.92 | D42: 0.03 | E42: 1 | F42: 1 | G42: 1
B43: Realistic | C43: 0.97 | D43: 0 | E43: 1 | F43: 1 | G43: 1
B44: Optimistic | C44: 0.99 | D44: -0.02 | E44: 1 | F44: 1 | G44: 1
...

Sheet Dashboard
B1: AY 2027-28 What-If Dashboard
B2: Enrollment, returnable contributions, cash flow & P&L — scenario planning
B4: Active Scenario: | C4: =Inputs!$C$4 -> Realistic | E4: (change it on the Inputs tab — every number below updates)
B6: Total Cash Inflow | E6: Total Cash Outflow | H6: Net Cash Flow | K6: P&L Net Surplus / (Deficit) | N6: Revenue Impact of Fee Increase | Q6: Returnable Fund — Closing Balance
B7: =CHOOSE(MATCH(Inputs!$C$4,{"Pessimistic","Realistic","Optimistic"},0),Calculations!C94,Calculations!D94,Calculations!E94) -> 134993100 | E7: =CHOOSE(MATCH(Inputs!$C$4,{"Pessimistic","Realistic","Optimistic"},0),Calculations!C98,Calculations!D98,Calculations!E98) -> 1.1716042e+08 | H7: =CHOOSE(MATCH(Inputs!$C$4,{"Pessimistic","Realistic","Optimistic"},0),Calculations!C99,Calculations!D99,Calculations!E99) -> 17832682 | K7: =CHOOSE(MATCH(Inputs!$C$4,{"Pessimistic","Realistic","Optimistic"},0),Calculations!C105,Calculations!D105,Calculations!E105) -> 8069581.7 | N7: =CHOOSE(MATCH(Inputs!$C$4,{"Pessimistic","Realistic","Optimistic"},0),Calculations!C109,Calculations!D109,Calculations!E109) -> 9383400 | Q7: =CHOOSE(MATCH(Inputs!$C$4,{"Pessimistic","Realistic","Optimistic"},0),Calculations!C114,Calculations!D114,Calculations!E114) -> 13520000
B11: Scenario Comparison — P&L & Cash Flow
B12: Metric | C12: Pessimistic | D12: Realistic | E12: Optimistic
B13: New Joiners (count) | C13: =Calculations!C86 -> 48 | D13: =Calculations!D86 -> 68 | E13: =Calculations!E86 -> 104
B14: Possible Dropouts (count) | C14: =Calculations!C87 -> 45 | D14: =Calculations!D87 -> 28 | E14: =Calculations!E87 -> 17
B15: Total Students | C15: =Calculations!C88 -> 369 | D15: =Calculations!D88 -> 406 | E15: =Calculations!E88 -> 453
B16: Tuition Fee Revenue (₹, accrual) | C16: =Calculations!C89 -> 114619600 | D16: =Calculations!D89 -> 125230000 | E16: =Calculations!E89 -> 139087000
B17: Tuition Fee Cash Collected (₹) | C17: =Calculations!C91 -> 105450032 | D17: =Calculations!D91 -> 121473100 | E17: =Calculations!E91 -> 137696130
B18: Returnable Contribution Collected (₹) | C18: =Calculations!C92 -> 3440000 | D18: =Calculations!D92 -> 6720000 | E18: =Calculations!E92 -> 10060000
B19: Advance from New Joiners Collected (₹) | C19: =Calculations!C93 -> 4800000 | D19: =Calculations!D93 -> 6800000 | E19: =Calculations!E93 -> 10400000
B20: Total Cash Inflow (₹) | C20: =Calculations!C94 -> 113690032 | D20: =Calculations!D94 -> 134993100 | E20: =Calculations!E94 -> 158156130
B21: Total Cash Outflow (₹) | C21: =Calculations!C98 -> 1.2067523e+08 | D21: =Calculations!D98 -> 1.1716042e+08 | E21: =Calculations!E98 -> 1.1481721e+08
B22: Net Cash Flow (₹) | C22: =Calculations!C99 -> -6985198.9 | D22: =Calculations!D99 -> 17832682 | E22: =Calculations!E99 -> 43338920
B23: P&L Total Revenue (₹) | C23: =Calculations!C103 -> 114619600 | D23: =Calculations!D103 -> 125230000 | E23: =Calculations!E103 -> 139087000
B24: P&L Total Operating Expenses (₹) | C24: =Calculations!C104 -> 1.2067523e+08 | D24: =Calculations!D104 -> 1.1716042e+08 | E24: =Calculations!E104 -> 1.1481721e+08
B25: P&L Net Surplus / (Deficit) (₹) | C25: =Calculations!C105 -> -6055630.9 | D25: =Calculations!D105 -> 8069581.7 | E25: =Calculations!E105 -> 24269790
B26: Fee-Increase Breakeven Dropout Threshold (count, fixed) | C26: =Calculations!C107 -> 54 | D26: =Calculations!D107 -> 54 | E26: =Calculations!E107 -> 54
B27: Headroom vs Breakeven Dropouts (count) | C27: =Calculations!C108 -> 9 | D27: =Calculations!D108 -> 26 | E27: =Calculations!E108 -> 37
B28: Revenue Impact of Fee Increase vs No-Increase (₹) | C28: =Calculations!C109 -> 4294200 | D28: =Calculations!D109 -> 9383400 | E28: =Calculations!E109 -> 12649800
B29: Returnable Fund — Closing Balance (₹) | C29: =Calculations!C114 -> 8240000 | D29: =Calculations!D114 -> 13520000 | E29: =Calculations!E114 -> 20460000
B32: Grade-wise Detail — Active Scenario
B33: Grade | C33: Existing Students | D33: New Joiners | E33: Total Students | F33: Tuition Fee Revenue (₹) | G33: Contribution % | H33: Contribution Collected (₹) | I33: Advance Collected (₹) | J33: Possible Dropouts
B34: =CHOOSE(MATCH(Inputs!$C$4,{"Pessimistic","Realistic","Optimistic"},0),Calculations!B6,Calculations!B26,Calculations!B46) -> Pre-KG | C34: =CHOOSE(MATCH(Inputs!$C$4,{"Pessimistic","Realistic","Optimistic"},0),Calculations!C6,Calculations!C26,Calculations!C46) -> 0 | D34: =CHOOSE(MATCH(Inputs!$C$4,{"Pessimistic","Realistic","Optimistic"},0),Calculations!D6,Calculations!D26,Calculations!D46) -> 0 | E34: =CHOOSE(MATCH(Inputs!$C$4,{"Pessimistic","Realistic","Optimistic"},0),Calculations!E6,Calculations!E26,Calculations!E46) -> 0 | F34: =CHOOSE(MATCH(Inputs!$C$4,{"Pessimistic","Realistic","Optimistic"},0),Calculations!F6,Calculations!F26,Calculations!F46) -> 0 | G34: =CHOOSE(MATCH(Inputs!$C$4,{"Pessimistic","Realistic","Optimistic"},0),Calculations!G6,Calculations!G26,Calculations!G46) -> 0 | H34: =CHOOSE(MATCH(Inputs!$C$4,{"Pessimistic","Realistic","Optimistic"},0),Calculations!H6,Calculations!H26,Calculations!H46) -> 0 | I34: =CHOOSE(MATCH(Inputs!$C$4,{"Pessimistic","Realistic","Optimistic"},0),Calculations!I6,Calculations!I26,Calculations!I46) -> 0 | J34: =CHOOSE(MATCH(Inputs!$C$4,{"Pessimistic","Realistic","Optimistic"},0),Calculations!J6,Calculations!J26,Calculations!J46) -> 0
B35: =CHOOSE(MATCH(Inputs!$C$4,{"Pessimistic","Realistic","Optimistic"},0),Calculations!B7,Calculations!B27,Calculations!B47) -> LKG | C35: =CHOOSE(MATCH(Inputs!$C$4,{"Pessimistic","Realistic","Optimistic"},0),Calculations!C7,Calculations!C27,Calculations!C47) -> 4 | D35: =CHOOSE(MATCH(Inputs!$C$4,{"Pessimistic","Realistic","Optimistic"},0),Calculations!D7,Calculations!D27,Calculations!D47) -> 18 | E35: =CHOOSE(MATCH(Inputs!$C$4,{"Pessimistic","Realistic","Optimistic"},0),Calculations!E7,Calculations!E27,Calculations!E47) -> 22 | F35: =CHOOSE(MATCH(Inputs!$C$4,{"Pessimistic","Realistic","Optimistic"},0),Calculations!F7,Calculations!F27,Calculations!F47) -> 4620000 | G35: =CHOOSE(MATCH(Inputs!$C$4,{"Pessimistic","Realistic","Optimistic"},0),Calculations!G7,Calculations!G27,Calculations!G47) -> 0 | H35: =CHOOSE(MATCH(Inputs!$C$4,{"Pessimistic","Realistic","Optimistic"},0),Calculations!H7,Calculations!H27,Calculations!H47) -> 0 | I35: =CHOOSE(MATCH(Inputs!$C$4,{"Pessimistic","Realistic","Optimistic"},0),Calculations!I7,Calculations!I27,Calculations!I47) -> 1800000 | J35: =CHOOSE(MATCH(Inputs!$C$4,{"Pessimistic","Realistic","Optimistic"},0),Calculations!J7,Calculations!J27,Calculations!J47) -> 0
B36: =CHOOSE(MATCH(Inputs!$C$4,{"Pessimistic","Realistic","Optimistic"},0),Calculations!B8,Calculations!B28,Calculations!B48) -> UKG | C36: =CHOOSE(MATCH(Inputs!$C$4,{"Pessimistic","Realistic","Optimistic"},0),Calculations!C8,Calculations!C28,Calculations!C48) -> 15 | D36: =CHOOSE(MATCH(Inputs!$C$4,{"Pessimistic","Realistic","Optimistic"},0),Calculations!D8,Calculations!D28,Calculations!D48) -> 11 | E36: =CHOOSE(MATCH(Inputs!$C$4,{"Pessimistic","Realistic","Optimistic"},0),Calculations!E8,Calculations!E28,Calculations!E48) -> 26 | F36: =CHOOSE(MATCH(Inputs!$C$4,{"Pessimistic","Realistic","Optimistic"},0),Calculations!F8,Calculations!F28,Calculations!F48) -> 5226000 | G36: =CHOOSE(MATCH(Inputs!$C$4,{"Pessimistic","Realistic","Optimistic"},0),Calculations!G8,Calculations!G28,Calculations!G48) -> 0 | H36: =CHOOSE(MATCH(Inputs!$C$4,{"Pessimistic","Realistic","Optimistic"},0),Calculations!H8,Calculations!H28,Calculations!H48) -> 0 | I36: =CHOOSE(MATCH(Inputs!$C$4,{"Pessimistic","Realistic","Optimistic"},0),Calculations!I8,Calculations!I28,Calculations!I48) -> 1100000 | J36: =CHOOSE(MATCH(Inputs!$C$4,{"Pessimistic","Realistic","Optimistic"},0),Calculations!J8,Calculations!J28,Calculations!J48) -> 0
B37: =CHOOSE(MATCH(Inputs!$C$4,{"Pessimistic","Realistic","Optimistic"},0),Calculations!B9,Calculations!B29,Calculations!B49) -> I | C37: =CHOOSE(MATCH(Inputs!$C$4,{"Pessimistic","Realistic","Optimistic"},0),Calculations!C9,Calculations!C29,Calculations!C49) -> 23 | D37: =CHOOSE(MATCH(Inputs!$C$4,{"Pessimistic","Realistic","Optimistic"},0),Calculations!D9,Calculations!D29,Calculations!D49) -> 11 | E37: =CHOOSE(MATCH(Inputs!$C$4,{"Pessimistic","Realistic","Optimistic"},0),Calculations!E9,Calculations!E29,Calculations!E49) -> 34 | F37: =CHOOSE(MATCH(Inputs!$C$4,{"Pessimistic","Realistic","Optimistic"},0),Calculations!F9,Calculations!F29,Calculations!F49) -> 7378000 | G37: =CHOOSE(MATCH(Inputs!$C$4,{"Pessimistic","Realistic","Optimistic"},0),Calculations!G9,Calculations!G29,Calculations!G49) -> 0 | H37: =CHOOSE(MATCH(Inputs!$C$4,{"Pessimistic","Realistic","Optimistic"},0),Calculations!H9,Calculations!H29,Calculations!H49) -> 0 | I37: =CHOOSE(MATCH(Inputs!$C$4,{"Pessimistic","Realistic","Optimistic"},0),Calculations!I9,Calculations!I29,Calculations!I49) -> 1100000 | J37: =CHOOSE(MATCH(Inputs!$C$4,{"Pessimistic","Realistic","Optimistic"},0),Calculations!J9,Calculations!J29,Calculations!J49) -> 0
B38: =CHOOSE(MATCH(Inputs!$C$4,{"Pessimistic","Realistic","Optimistic"},0),Calculations!B10,Calculations!B30,Calculations!B50) -> II | C38: =CHOOSE(MATCH(Inputs!$C$4,{"Pessimistic","Realistic","Optimistic"},0),Calculations!C10,Calculations!C30,Calculations!C50) -> 33 | D38: =CHOOSE(MATCH(Inputs!$C$4,{"Pessimistic","Realistic","Optimistic"},0),Calculations!D10,Calculations!D30,Calculations!D50) -> 0 | E38: =CHOOSE(MATCH(Inputs!$C$4,{"Pessimistic","Realistic","Optimistic"},0),Calculations!E10,Calculations!E30,Calculations!E50) -> 28 | F38: =CHOOSE(MATCH(Inputs!$C$4,{"Pessimistic","Realistic","Optimistic"},0),Calculations!F10,Calculations!F30,Calculations!F50) -> 7291200 | G38: =CHOOSE(MATCH(Inputs!$C$4,{"Pessimistic","Realistic","Optimistic"},0),Calculations!G10,Calculations!G30,Calculations!G50) -> 0 | H38: =CHOOSE(MATCH(Inputs!$C$4,{"Pessimistic","Realistic","Optimistic"},0),Calculations!H10,Calculations!H30,Calculations!H50) -> 0 | I38: =CHOOSE(MATCH(Inputs!$C$4,{"Pessimistic","Realistic","Optimistic"},0),Calculations!I10,Calculations!I30,Calculations!I50) -> 0 | J38: =CHOOSE(MATCH(Inputs!$C$4,{"Pessimistic","Realistic","Optimistic"},0),Calculations!J10,Calculations!J30,Calculations!J50) -> 5
B39: =CHOOSE(MATCH(Inputs!$C$4,{"Pessimistic","Realistic","Optimistic"},0),Calculations!B11,Calculations!B31,Calculations!B51) -> III | C39: =CHOOSE(MATCH(Inputs!$C$4,{"Pessimistic","Realistic","Optimistic"},0),Calculations!C11,Calculations!C31,Calculations!C51) -> 34 | D39: =CHOOSE(MATCH(Inputs!$C$4,{"Pessimistic","Realistic","Optimistic"},0),Calculations!D11,Calculations!D31,Calculations!D51) -> 0 | E39: =CHOOSE(MATCH(Inputs!$C$4,{"Pessimistic","Realistic","Optimistic"},0),Calculations!E11,Calculations!E31,Calculations!E51) -> 29 | F39: =CHOOSE(MATCH(Inputs!$C$4,{"Pessimistic","Realistic","Optimistic"},0),Calculations!F11,Calculations!F31,Calculations!F51) -> 7899600 | G39: =CHOOSE(MATCH(Inputs!$C$4,{"Pessimistic","Realistic","Optimistic"},0),Calculations!G11,Calculations!G31,Calculations!G51) -> 0 | H39: =CHOOSE(MATCH(Inputs!$C$4,{"Pessimistic","Realistic","Optimistic"},0),Calculations!H11,Calculations!H31,Calculations!H51) -> 0 | I39: =CHOOSE(MATCH(Inputs!$C$4,{"Pessimistic","Realistic","Optimistic"},0),Calculations!I11,Calculations!I31,Calculations!I51) -> 0 | J39: =CHOOSE(MATCH(Inputs!$C$4,{"Pessimistic","Realistic","Optimistic"},0),Calculations!J11,Calculations!J31,Calculations!J51) -> 5
B40: =CHOOSE(MATCH(Inputs!$C$4,{"Pessimistic","Realistic","Optimistic"},0),Calculations!B12,Calculations!B32,Calculations!B52) -> IV | C40: =CHOOSE(MATCH(Inputs!$C$4,{"Pessimistic","Realistic","Optimistic"},0),Calculations!C12,Calculations!C32,Calculations!C52) -> 32 | D40: =CHOOSE(MATCH(Inputs!$C$4,{"Pessimistic","Realistic","Optimistic"},0),Calculations!D12,Calculations!D32,Calculations!D52) -> 0 | E40: =CHOOSE(MATCH(Inputs!$C$4,{"Pessimistic","Realistic","Optimistic"},0),Calculations!E12,Calculations!E32,Calculations!E52) -> 27 | F40: =CHOOSE(MATCH(Inputs!$C$4,{"Pessimistic","Realistic","Optimistic"},0),Calculations!F12,Calculations!F32,Calculations!F52) -> 7516800 | G40: =CHOOSE(MATCH(Inputs!$C$4,{"Pessimistic","Realistic","Optimistic"},0),Calculations!G12,Calculations!G32,Calculations!G52) -> 0 | H40: =CHOOSE(MATCH(Inputs!$C$4,{"Pessimistic","Realistic","Optimistic"},0),Calculations!H12,Calculations!H32,Calculations!H52) -> 0 | I40: =CHOOSE(MATCH(Inputs!$C$4,{"Pessimistic","Realistic","Optimistic"},0),Calculations!I12,Calculations!I32,Calculations!I52) -> 0 | J40: =CHOOSE(MATCH(Inputs!$C$4,{"Pessimistic","Realistic","Optimistic"},0),Calculations!J12,Calculations!J32,Calculations!J52) -> 5
B41: =CHOOSE(MATCH(Inputs!$C$4,{"Pessimistic","Realistic","Optimistic"},0),Calculations!B13,Calculations!B33,Calculations!B53) -> V | C41: =CHOOSE(MATCH(Inputs!$C$4,{"Pessimistic","Realistic","Optimistic"},0),Calculations!C13,Calculations!C33,Calculations!C53) -> 31 | D41: =CHOOSE(MATCH(Inputs!$C$4,{"Pessimistic","Realistic","Optimistic"},0),Calculations!D13,Calculations!D33,Calculations!D53) -> 1 | E41: =CHOOSE(MATCH(Inputs!$C$4,{"Pessimistic","Realistic","Optimistic"},0),Calculations!E13,Calculations!E33,Calculations!E53) -> 27 | F41: =CHOOSE(MATCH(Inputs!$C$4,{"Pessimistic","Realistic","Optimistic"},0),Calculations!F13,Calculations!F33,Calculations!F53) -> 8229600 | G41: =CHOOSE(MATCH(Inputs!$C$4,{"Pessimistic","Realistic","Optimistic"},0),Calculations!G13,Calculations!G33,Calculations!G53) -> 0 | H41: =CHOOSE(MATCH(Inputs!$C$4,{"Pessimistic","Realistic","Optimistic"},0),Calculations!H13,Calculations!H33,Calculations!H53) -> 0 | I41: =CHOOSE(MATCH(Inputs!$C$4,{"Pessimistic","Realistic","Optimistic"},0),Calculations!I13,Calculations!I33,Calculations!I53) -> 100000 | J41: =CHOOSE(MATCH(Inputs!$C$4,{"Pessimistic","Realistic","Optimistic"},0),Calculations!J13,Calculations!J33,Calculations!J53) -> 5
B42: =CHOOSE(MATCH(Inputs!$C$4,{"Pessimistic","Realistic","Optimistic"},0),Calculations!B14,Calculations!B34,Calculations!B54) -> VI | C42: =CHOOSE(MATCH(Inputs!$C$4,{"Pessimistic","Realistic","Optimistic"},0),Calculations!C14,Calculations!C34,Calculations!C54) -> 31 | D42: =CHOOSE(MATCH(Inputs!$C$4,{"Pessimistic","Realistic","Optimistic"},0),Calculations!D14,Calculations!D34,Calculations!D54) -> 1 | E42: =CHOOSE(MATCH(Inputs!$C$4,{"Pessimistic","Realistic","Optimistic"},0),Calculations!E14,Calculations!E34,Calculations!E54) -> 29 | F42: =CHOOSE(MATCH(Inputs!$C$4,{"Pessimistic","Realistic","Optimistic"},0),Calculations!F14,Calculations!F34,Calculations!F54) -> 9396000 | G42: =CHOOSE(MATCH(Inputs!$C$4,{"Pessimistic","Realistic","Optimistic"},0),Calculations!G14,Calculations!G34,Calculations!G54) -> 0.2 | H42: =CHOOSE(MATCH(Inputs!$C$4,{"Pessimistic","Realistic","Optimistic"},0),Calculations!H14,Calculations!H34,Calculations!H54) -> 1120000 | I42: =CHOOSE(MATCH(Inputs!$C$4,{"Pessimistic","Realistic","Optimistic"},0),Calculations!I14,Calculations!I34,Calculations!I54) -> 100000 | J42: =CHOOSE(MATCH(Inputs!$C$4,{"Pessimistic","Realistic","Optimistic"},0),Calculations!J14,Calculations!J34,Calculations!J54) -> 3
B43: =CHOOSE(MATCH(Inputs!$C$4,{"Pessimistic","Realistic","Optimistic"},0),Calculations!B15,Calculations!B35,Calculations!B55) -> VII | C43: =CHOOSE(MATCH(Inputs!$C$4,{"Pessimistic","Realistic","Optimistic"},0),Calculations!C15,Calculations!C35,Calculations!C55) -> 27 | D43: =CHOOSE(MATCH(Inputs!$C$4,{"Pessimistic","Realistic","Optimistic"},0),Calculations!D15,Calculations!D35,Calculations!D55) -> 2 | E43: =CHOOSE(MATCH(Inputs!$C$4,{"Pessimistic","Realistic","Optimistic"},0),Calculations!E15,Calculations!E35,Calculations!E55) -> 27 | F43: =CHOOSE(MATCH(Inputs!$C$4,{"Pessimistic","Realistic","Optimistic"},0),Calculations!F15,Calculations!F35,Calculations!F55) -> 9331200 | G43: =CHOOSE(MATCH(Inputs!$C$4,{"Pessimistic","Realistic","Optimistic"},0),Calculations!G15,Calculations!G35,Calculations!G55) -> 0.2 | H43: =CHOOSE(MATCH(Inputs!$C$4,{"Pessimistic","Realistic","Optimistic"},0),Calculations!H15,Calculations!H35,Calculations!H55) -> 1000000 | I43: =CHOOSE(MATCH(Inputs!$C$4,{"Pessimistic","Realistic","Optimistic"},0),Calculations!I15,Calculations!I35,Calculations!I55) -> 200000 | J43: =CHOOSE(MATCH(Inputs!$C$4,{"Pessimistic","Realistic","Optimistic"},0),Calculations!J15,Calculations!J35,Calculations!J55) -> 2
B44: =CHOOSE(MATCH(Inputs!$C$4,{"Pessimistic","Realistic","Optimistic"},0),Calculations!B16,Calculations!B36,Calculations!B56) -> VIII | C44: =CHOOSE(MATCH(Inputs!$C$4,{"Pessimistic","Realistic","Optimistic"},0),Calculations!C16,Calculations!C36,Calculations!C56) -> 25 | D44: =CHOOSE(MATCH(Inputs!$C$4,{"Pessimistic","Realistic","Optimistic"},0),Calculations!D16,Calculations!D36,Calculations!D56) -> 3 | E44: =CHOOSE(MATCH(Inputs!$C$4,{"Pessimistic","Realistic","Optimistic"},0),Calculations!E16,Calculations!E36,Calculations!E56) -> 26 | F44: =CHOOSE(MATCH(Inputs!$C$4,{"Pessimistic","Realistic","Optimistic"},0),Calculations!F16,Calculations!F36,Calculations!F56) -> 9484800 | G44: =CHOOSE(MATCH(Inputs!$C$4,{"Pessimistic","Realistic","Optimistic"},0),Calculations!G16,Calculations!G36,Calculations!G56) -> 0.3 | H44: =CHOOSE(MATCH(Inputs!$C$4,{"Pessimistic","Realistic","Optimistic"},0),Calculations!H16,Calculations!H36,Calculations!H56) -> 1380000 | I44: =CHOOSE(MATCH(Inputs!$C$4,{"Pessimistic","Realistic","Optimistic"},0),Calculations!I16,Calculations!I36,Calculations!I56) -> 300000 | J44: =CHOOSE(MATCH(Inputs!$C$4,{"Pessimistic","Realistic","Optimistic"},0),Calculations!J16,Calculations!J36,Calculations!J56) -> 2
B45: =CHOOSE(MATCH(Inputs!$C$4,{"Pessimistic","Realistic","Optimistic"},0),Calculations!B17,Calculations!B37,Calculations!B57) -> IX | C45: =CHOOSE(MATCH(Inputs!$C$4,{"Pessimistic","Realistic","Optimistic"},0),Calculations!C17,Calculations!C37,Calculations!C57) -> 26 | D45: =CHOOSE(MATCH(Inputs!$C$4,{"Pessimistic","Realistic","Optimistic"},0),Calculations!D17,Calculations!D37,Calculations!D57) -> 3 | E45: =CHOOSE(MATCH(Inputs!$C$4,{"Pessimistic","Realistic","Optimistic"},0),Calculations!E17,Calculations!E37,Calculations!E57) -> 28 | F45: =CHOOSE(MATCH(Inputs!$C$4,{"Pessimistic","Realistic","Optimistic"},0),Calculations!F17,Calculations!F37,Calculations!F57) -> 10718400 | G45: =CHOOSE(MATCH(Inputs!$C$4,{"Pessimistic","Realistic","Optimistic"},0),Calculations!G17,Calculations!G37,Calculations!G57) -> 0.3 | H45: =CHOOSE(MATCH(Inputs!$C$4,{"Pessimistic","Realistic","Optimistic"},0),Calculations!H17,Calculations!H37,Calculations!H57) -> 1500000 | I45: =CHOOSE(MATCH(Inputs!$C$4,{"Pessimistic","Realistic","Optimistic"},0),Calculations!I17,Calculations!I37,Calculations!I57) -> 300000 | J45: =CHOOSE(MATCH(Inputs!$C$4,{"Pessimistic","Realistic","Optimistic"},0),Calculations!J17,Calculations!J37,Calculations!J57) -> 1
... B48: =CHOOSE(MATCH(Inputs!$C$4,{"Pessimistic","Realistic","Optimistic"},0),Calculations!B20,Calculations!B40,Calculations!B60) -> A2 | C48: =CHOOSE(MATCH(Inputs!$C$4,{"Pessimistic","Realistic","Optimistic"},0),Calculations!C20,Calculations!C40,Calculations!C60) -> 29 | D48: =CHOOSE(MATCH(Inputs!$C$4,{"Pessimistic","Realistic","Optimistic"},0),Calculations!D20,Calculations!D40,Calculations!D60) -> 1 | E48: =CHOOSE(MATCH(Inputs!$C$4,{"Pessimistic","Realistic","Optimistic"},0),Calculations!E20,Calculations!E40,Calculations!E60) -> 30 | F48: =CHOOSE(MATCH(Inputs!$C$4,{"Pessimistic","Realistic","Optimistic"},0),Calculations!F20,Calculations!F40,Calculations!F60) -> 11016000 | G48: =CHOOSE(MATCH(Inputs!$C$4,{"Pessimistic","Realistic","Optimistic"},0),Calculations!G20,Calculations!G40,Calculations!G60) -> 0 | H48: =CHOOSE(MATCH(Inputs!$C$4,{"Pessimistic","Realistic","Optimistic"},0),Calculations!H20,Calculations!H40,Calculations!H60) -> 0 | I48: =CHOOSE(MATCH(Inputs!$C$4,{"Pessimistic","Realistic","Optimistic"},0),Calculations!I20,Calculations!I40,Calculations!I60) -> 100000 | J48: =CHOOSE(MATCH(Inputs!$C$4,{"Pessimistic","Realistic","Optimistic"},0),Calculations!J20,Calculations!J40,Calculations!J60) -> 0
B49: Total | C49: =SUM(C34:C48) -> 366 | D49: =SUM(D34:D48) -> 68 | E49: =SUM(E34:E48) -> 406 | F49: =SUM(F34:F48) -> 125230000 | H49: =SUM(H34:H48) -> 6720000 | I49: =SUM(I34:I48) -> 6800000 | J49: =SUM(J34:J48) -> 28

Sheet Calculations
B1: Calculations — Scenario Engine
B2: Grade-by-grade math for each scenario. Everything here is a formula pulling from Inputs — normally no need to edit.
B4: PESSIMISTIC SCENARIO
B5: Grade | C5: Existing Students | D5: New Joiners | E5: Total Students | F5: Tuition Fee Revenue (₹) | G5: Contribution % | H5: Contribution Collected (₹) | I5: Advance Collected (₹) | J5: Possible Dropouts
B6: =Inputs!B8 -> Pre-KG | C6: =Inputs!C8 -> 0 | D6: =MIN(Inputs!F8,MAX(0,ROUND(Inputs!F8*Inputs!H8*Inputs!$E$42,0))) -> 0 | E6: =C6-J6+D6 -> 0 | F6: =E6*Inputs!D8*(1+Inputs!E8) -> 0 | G6: =MIN(1,MAX(0,Inputs!I8+Inputs!J8*Inputs!$F$42)) -> 0 | H6: =(C6-J6)*G6*Inputs!L8 -> 0 | I6: =D6*Inputs!M8 -> 0 | J6: =MAX(0,ROUND(Inputs!N8*(1+Inputs!O8*Inputs!$G$42),0)) -> 0
B7: =Inputs!B9 -> LKG | C7: =Inputs!C9 -> 4 | D7: =MIN(Inputs!F9,MAX(0,ROUND(Inputs!F9*Inputs!H9*Inputs!$E$42,0))) -> 13 | E7: =C7-J7+D7 -> 17 | F7: =E7*Inputs!D9*(1+Inputs!E9) -> 3570000 | G7: =MIN(1,MAX(0,Inputs!I9+Inputs!J9*Inputs!$F$42)) -> 0 | H7: =(C7-J7)*G7*Inputs!L9 -> 0 | I7: =D7*Inputs!M9 -> 1300000 | J7: =MAX(0,ROUND(Inputs!N9*(1+Inputs!O9*Inputs!$G$42),0)) -> 0
B8: =Inputs!B10 -> UKG | C8: =Inputs!C10 -> 15 | D8: =MIN(Inputs!F10,MAX(0,ROUND(Inputs!F10*Inputs!H10*Inputs!$E$42,0))) -> 8 | E8: =C8-J8+D8 -> 23 | F8: =E8*Inputs!D10*(1+Inputs!E10) -> 4623000 | G8: =MIN(1,MAX(0,Inputs!I10+Inputs!J10*Inputs!$F$42)) -> 0 | H8: =(C8-J8)*G8*Inputs!L10 -> 0 | I8: =D8*Inputs!M10 -> 800000 | J8: =MAX(0,ROUND(Inputs!N10*(1+Inputs!O10*Inputs!$G$42),0)) -> 0
B9: =Inputs!B11 -> I | C9: =Inputs!C11 -> 23 | D9: =MIN(Inputs!F11,MAX(0,ROUND(Inputs!F11*Inputs!H11*Inputs!$E$42,0))) -> 8 | E9: =C9-J9+D9 -> 31 | F9: =E9*Inputs!D11*(1+Inputs!E11) -> 6727000 | G9: =MIN(1,MAX(0,Inputs!I11+Inputs!J11*Inputs!$F$42)) -> 0 | H9: =(C9-J9)*G9*Inputs!L11 -> 0 | I9: =D9*Inputs!M11 -> 800000 | J9: =MAX(0,ROUND(Inputs!N11*(1+Inputs!O11*Inputs!$G$42),0)) -> 0
B10: =Inputs!B12 -> II | C10: =Inputs!C12 -> 33 | D10: =MIN(Inputs!F12,MAX(0,ROUND(Inputs!F12*Inputs!H12*Inputs!$E$42,0))) -> 0 | E10: =C10-J10+D10 -> 25 | F10: =E10*Inputs!D12*(1+Inputs!E12) -> 6510000 | G10: =MIN(1,MAX(0,Inputs!I12+Inputs!J12*Inputs!$F$42)) -> 0 | H10: =(C10-J10)*G10*Inputs!L12 -> 0 | I10: =D10*Inputs!M12 -> 0 | J10: =MAX(0,ROUND(Inputs!N12*(1+Inputs!O12*Inputs!$G$42),0)) -> 8
B11: =Inputs!B13 -> III | C11: =Inputs!C13 -> 34 | D11: =MIN(Inputs!F13,MAX(0,ROUND(Inputs!F13*Inputs!H13*Inputs!$E$42,0))) -> 0 | E11: =C11-J11+D11 -> 26 | F11: =E11*Inputs!D13*(1+Inputs!E13) -> 7082400 | G11: =MIN(1,MAX(0,Inputs!I13+Inputs!J13*Inputs!$F$42)) -> 0 | H11: =(C11-J11)*G11*Inputs!L13 -> 0 | I11: =D11*Inputs!M13 -> 0 | J11: =MAX(0,ROUND(Inputs!N13*(1+Inputs!O13*Inputs!$G$42),0)) -> 8
B12: =Inputs!B14 -> IV | C12: =Inputs!C14 -> 32 | D12: =MIN(Inputs!F14,MAX(0,ROUND(Inputs!F14*Inputs!H14*Inputs!$E$42,0))) -> 0 | E12: =C12-J12+D12 -> 24 | F12: =E12*Inputs!D14*(1+Inputs!E14) -> 6681600 | G12: =MIN(1,MAX(0,Inputs!I14+Inputs!J14*Inputs!$F$42)) -> 0 | H12: =(C12-J12)*G12*Inputs!L14 -> 0 | I12: =D12*Inputs!M14 -> 0 | J12: =MAX(0,ROUND(Inputs!N14*(1+Inputs!O14*Inputs!$G$42),0)) -> 8
B13: =Inputs!B15 -> V | C13: =Inputs!C15 -> 31 | D13: =MIN(Inputs!F15,MAX(0,ROUND(Inputs!F15*Inputs!H15*Inputs!$E$42,0))) -> 1 | E13: =C13-J13+D13 -> 24 | F13: =E13*Inputs!D15*(1+Inputs!E15) -> 7315200 | G13: =MIN(1,MAX(0,Inputs!I15+Inputs!J15*Inputs!$F$42)) -> 0 | H13: =(C13-J13)*G13*Inputs!L15 -> 0 | I13: =D13*Inputs!M15 -> 100000 | J13: =MAX(0,ROUND(Inputs!N15*(1+Inputs!O15*Inputs!$G$42),0)) -> 8
B14: =Inputs!B16 -> VI | C14: =Inputs!C16 -> 31 | D14: =MIN(Inputs!F16,MAX(0,ROUND(Inputs!F16*Inputs!H16*Inputs!$E$42,0))) -> 1 | E14: =C14-J14+D14 -> 27 | F14: =E14*Inputs!D16*(1+Inputs!E16) -> 8748000 | G14: =MIN(1,MAX(0,Inputs!I16+Inputs!J16*Inputs!$F$42)) -> 0.1 | H14: =(C14-J14)*G14*Inputs!L16 -> 520000 | I14: =D14*Inputs!M16 -> 100000 | J14: =MAX(0,ROUND(Inputs!N16*(1+Inputs!O16*Inputs!$G$42),0)) -> 5
B15: =Inputs!B17 -> VII | C15: =Inputs!C17 -> 27 | D15: =MIN(Inputs!F17,MAX(0,ROUND(Inputs!F17*Inputs!H17*Inputs!$E$42,0))) -> 2 | E15: =C15-J15+D15 -> 26 | F15: =E15*Inputs!D17*(1+Inputs!E17) -> 8985600 | G15: =MIN(1,MAX(0,Inputs!I17+Inputs!J17*Inputs!$F$42)) -> 0.1 | H15: =(C15-J15)*G15*Inputs!L17 -> 480000 | I15: =D15*Inputs!M17 -> 200000 | J15: =MAX(0,ROUND(Inputs!N17*(1+Inputs!O17*Inputs!$G$42),0)) -> 3
B16: =Inputs!B18 -> VIII | C16: =Inputs!C18 -> 25 | D16: =MIN(Inputs!F18,MAX(0,ROUND(Inputs!F18*Inputs!H18*Inputs!$E$42,0))) -> 2 | E16: =C16-J16+D16 -> 24 | F16: =E16*Inputs!D18*(1+Inputs!E18) -> 8755200 | G16: =MIN(1,MAX(0,Inputs!I18+Inputs!J18*Inputs!$F$42)) -> 0.2 | H16: =(C16-J16)*G16*Inputs!L18 -> 880000 | I16: =D16*Inputs!M18 -> 200000 | J16: =MAX(0,ROUND(Inputs!N18*(1+Inputs!O18*Inputs!$G$42),0)) -> 3
B17: =Inputs!B19 -> IX | C17: =Inputs!C19 -> 26 | D17: =MIN(Inputs!F19,MAX(0,ROUND(Inputs!F19*Inputs!H19*Inputs!$E$42,0))) -> 2 | E17: =C17-J17+D17 -> 26 | F17: =E17*Inputs!D19*(1+Inputs!E19) -> 9952800 | G17: =MIN(1,MAX(0,Inputs!I19+Inputs!J19*Inputs!$F$42)) -> 0.2 | H17: =(C17-J17)*G17*Inputs!L19 -> 960000 | I17: =D17*Inputs!M19 -> 200000 | J17: =MAX(0,ROUND(Inputs!N19*(1+Inputs!O19*Inputs!$G$42),0)) -> 2
... B20: =Inputs!B22 -> A2 | C20: =Inputs!C22 -> 29 | D20: =MIN(Inputs!F22,MAX(0,ROUND(Inputs!F22*Inputs!H22*Inputs!$E$42,0))) -> 1 | E20: =C20-J20+D20 -> 30 | F20: =E20*Inputs!D22*(1+Inputs!E22) -> 11016000 | G20: =MIN(1,MAX(0,Inputs!I22+Inputs!J22*Inputs!$F$42)) -> 0 | H20: =(C20-J20)*G20*Inputs!L22 -> 0 | I20: =D20*Inputs!M22 -> 100000 | J20: =MAX(0,ROUND(Inputs!N22*(1+Inputs!O22*Inputs!$G$42),0)) -> 0
B21: Total | C21: =SUM(C6:C20) -> 366 | D21: =SUM(D6:D20) -> 48 | E21: =SUM(E6:E20) -> 369 | F21: =SUM(F6:F20) -> 114619600 | H21: =SUM(H6:H20) -> 3440000 | I21: =SUM(I6:I20) -> 4800000 | J21: =SUM(J6:J20) -> 45
B24: REALISTIC SCENARIO
B25: Grade | C25: Existing Students | D25: New Joiners | E25: Total Students | F25: Tuition Fee Revenue (₹) | G25: Contribution % | H25: Contribution Collected (₹) | I25: Advance Collected (₹) | J25: Possible Dropouts
B26: =Inputs!B8 -> Pre-KG | C26: =Inputs!C8 -> 0 | D26: =MIN(Inputs!F8,MAX(0,ROUND(Inputs!F8*Inputs!G8*Inputs!$E$43,0))) -> 0 | E26: =C26-J26+D26 -> 0 | F26: =E26*Inputs!D8*(1+Inputs!E8) -> 0 | G26: =Inputs!I8 -> 0 | H26: =(C26-J26)*G26*Inputs!L8 -> 0 | I26: =D26*Inputs!M8 -> 0 | J26: =Inputs!N8 -> 0
B27: =Inputs!B9 -> LKG | C27: =Inputs!C9 -> 4 | D27: =MIN(Inputs!F9,MAX(0,ROUND(Inputs!F9*Inputs!G9*Inputs!$E$43,0))) -> 18 | E27: =C27-J27+D27 -> 22 | F27: =E27*Inputs!D9*(1+Inputs!E9) -> 4620000 | G27: =Inputs!I9 -> 0 | H27: =(C27-J27)*G27*Inputs!L9 -> 0 | I27: =D27*Inputs!M9 -> 1800000 | J27: =Inputs!N9 -> 0
B28: =Inputs!B10 -> UKG | C28: =Inputs!C10 -> 15 | D28: =MIN(Inputs!F10,MAX(0,ROUND(Inputs!F10*Inputs!G10*Inputs!$E$43,0))) -> 11 | E28: =C28-J28+D28 -> 26 | F28: =E28*Inputs!D10*(1+Inputs!E10) -> 5226000 | G28: =Inputs!I10 -> 0 | H28: =(C28-J28)*G28*Inputs!L10 -> 0 | I28: =D28*Inputs!M10 -> 1100000 | J28: =Inputs!N10 -> 0
B29: =Inputs!B11 -> I | C29: =Inputs!C11 -> 23 | D29: =MIN(Inputs!F11,MAX(0,ROUND(Inputs!F11*Inputs!G11*Inputs!$E$43,0))) -> 11 | E29: =C29-J29+D29 -> 34 | F29: =E29*Inputs!D11*(1+Inputs!E11) -> 7378000 | G29: =Inputs!I11 -> 0 | H29: =(C29-J29)*G29*Inputs!L11 -> 0 | I29: =D29*Inputs!M11 -> 1100000 | J29: =Inputs!N11 -> 0
B30: =Inputs!B12 -> II | C30: =Inputs!C12 -> 33 | D30: =MIN(Inputs!F12,MAX(0,ROUND(Inputs!F12*Inputs!G12*Inputs!$E$43,0))) -> 0 | E30: =C30-J30+D30 -> 28 | F30: =E30*Inputs!D12*(1+Inputs!E12) -> 7291200 | G30: =Inputs!I12 -> 0 | H30: =(C30-J30)*G30*Inputs!L12 -> 0 | I30: =D30*Inputs!M12 -> 0 | J30: =Inputs!N12 -> 5
B31: =Inputs!B13 -> III | C31: =Inputs!C13 -> 34 | D31: =MIN(Inputs!F13,MAX(0,ROUND(Inputs!F13*Inputs!G13*Inputs!$E$43,0))) -> 0 | E31: =C31-J31+D31 -> 29 | F31: =E31*Inputs!D13*(1+Inputs!E13) -> 7899600 | G31: =Inputs!I13 -> 0 | H31: =(C31-J31)*G31*Inputs!L13 -> 0 | I31: =D31*Inputs!M13 -> 0 | J31: =Inputs!N13 -> 5
B32: =Inputs!B14 -> IV | C32: =Inputs!C14 -> 32 | D32: =MIN(Inputs!F14,MAX(0,ROUND(Inputs!F14*Inputs!G14*Inputs!$E$43,0))) -> 0 | E32: =C32-J32+D32 -> 27 | F32: =E32*Inputs!D14*(1+Inputs!E14) -> 7516800 | G32: =Inputs!I14 -> 0 | H32: =(C32-J32)*G32*Inputs!L14 -> 0 | I32: =D32*Inputs!M14 -> 0 | J32: =Inputs!N14 -> 5
B33: =Inputs!B15 -> V | C33: =Inputs!C15 -> 31 | D33: =MIN(Inputs!F15,MAX(0,ROUND(Inputs!F15*Inputs!G15*Inputs!$E$43,0))) -> 1 | E33: =C33-J33+D33 -> 27 | F33: =E33*Inputs!D15*(1+Inputs!E15) -> 8229600 | G33: =Inputs!I15 -> 0 | H33: =(C33-J33)*G33*Inputs!L15 -> 0 | I33: =D33*Inputs!M15 -> 100000 | J33: =Inputs!N15 -> 5
B34: =Inputs!B16 -> VI | C34: =Inputs!C16 -> 31 | D34: =MIN(Inputs!F16,MAX(0,ROUND(Inputs!F16*Inputs!G16*Inputs!$E$43,0))) -> 1 | E34: =C34-J34+D34 -> 29 | F34: =E34*Inputs!D16*(1+Inputs!E16) -> 9396000 | G34: =Inputs!I16 -> 0.2 | H34: =(C34-J34)*G34*Inputs!L16 -> 1120000 | I34: =D34*Inputs!M16 -> 100000 | J34: =Inputs!N16 -> 3
B35: =Inputs!B17 -> VII | C35: =Inputs!C17 -> 27 | D35: =MIN(Inputs!F17,MAX(0,ROUND(Inputs!F17*Inputs!G17*Inputs!$E$43,0))) -> 2 | E35: =C35-J35+D35 -> 27 | F35: =E35*Inputs!D17*(1+Inputs!E17) -> 9331200 | G35: =Inputs!I17 -> 0.2 | H35: =(C35-J35)*G35*Inputs!L17 -> 1000000 | I35: =D35*Inputs!M17 -> 200000 | J35: =Inputs!N17 -> 2
B36: =Inputs!B18 -> VIII | C36: =Inputs!C18 -> 25 | D36: =MIN(Inputs!F18,MAX(0,ROUND(Inputs!F18*Inputs!G18*Inputs!$E$43,0))) -> 3 | E36: =C36-J36+D36 -> 26 | F36: =E36*Inputs!D18*(1+Inputs!E18) -> 9484800 | G36: =Inputs!I18 -> 0.3 | H36: =(C36-J36)*G36*Inputs!L18 -> 1380000 | I36: =D36*Inputs!M18 -> 300000 | J36: =Inputs!N18 -> 2
B37: =Inputs!B19 -> IX | C37: =Inputs!C19 -> 26 | D37: =MIN(Inputs!F19,MAX(0,ROUND(Inputs!F19*Inputs!G19*Inputs!$E$43,0))) -> 3 | E37: =C37-J37+D37 -> 28 | F37: =E37*Inputs!D19*(1+Inputs!E19) -> 10718400 | G37: =Inputs!I19 -> 0.3 | H37: =(C37-J37)*G37*Inputs!L19 -> 1500000 | I37: =D37*Inputs!M19 -> 300000 | J37: =Inputs!N19 -> 1
... B40: =Inputs!B22 -> A2 | C40: =Inputs!C22 -> 29 | D40: =MIN(Inputs!F22,MAX(0,ROUND(Inputs!F22*Inputs!G22*Inputs!$E$43,0))) -> 1 | E40: =C40-J40+D40 -> 30 | F40: =E40*Inputs!D22*(1+Inputs!E22) -> 11016000 | G40: =Inputs!I22 -> 0 | H40: =(C40-J40)*G40*Inputs!L22 -> 0 | I40: =D40*Inputs!M22 -> 100000 | J40: =Inputs!N22 -> 0
B41: Total | C41: =SUM(C26:C40) -> 366 | D41: =SUM(D26:D40) -> 68 | E41: =SUM(E26:E40) -> 406 | F41: =SUM(F26:F40) -> 125230000 | H41: =SUM(H26:H40) -> 6720000 | I41: =SUM(I26:I40) -> 6800000 | J41: =SUM(J26:J40) -> 28
B44: OPTIMISTIC SCENARIO
B45: Grade | C45: Existing Students | D45: New Joiners | E45: Total Students | F45: Tuition Fee Revenue (₹) | G45: Contribution % | H45: Contribution Collected (₹) | I45: Advance Collected (₹) | J45: Possible Dropouts
B46: =Inputs!B8 -> Pre-KG | C46: =Inputs!C8 -> 0 | D46: =Inputs!F8 -> 0 | E46: =C46-J46+D46 -> 0 | F46: =E46*Inputs!D8*(1+Inputs!E8) -> 0 | G46: =MIN(1,MAX(0,Inputs!I8+Inputs!K8*Inputs!$F$44)) -> 0 | H46: =(C46-J46)*G46*Inputs!L8 -> 0 | I46: =D46*Inputs!M8 -> 0 | J46: =MAX(0,ROUND(Inputs!N8*(1+Inputs!P8*Inputs!$G$44),0)) -> 0
B47: =Inputs!B9 -> LKG | C47: =Inputs!C9 -> 4 | D47: =Inputs!F9 -> 26 | E47: =C47-J47+D47 -> 30 | F47: =E47*Inputs!D9*(1+Inputs!E9) -> 6300000 | G47: =MIN(1,MAX(0,Inputs!I9+Inputs!K9*Inputs!$F$44)) -> 0 | H47: =(C47-J47)*G47*Inputs!L9 -> 0 | I47: =D47*Inputs!M9 -> 2600000 | J47: =MAX(0,ROUND(Inputs!N9*(1+Inputs!P9*Inputs!$G$44),0)) -> 0
B48: =Inputs!B10 -> UKG | C48: =Inputs!C10 -> 15 | D48: =Inputs!F10 -> 15 | E48: =C48-J48+D48 -> 30 | F48: =E48*Inputs!D10*(1+Inputs!E10) -> 6030000 | G48: =MIN(1,MAX(0,Inputs!I10+Inputs!K10*Inputs!$F$44)) -> 0 | H48: =(C48-J48)*G48*Inputs!L10 -> 0 | I48: =D48*Inputs!M10 -> 1500000 | J48: =MAX(0,ROUND(Inputs!N10*(1+Inputs!P10*Inputs!$G$44),0)) -> 0
B49: =Inputs!B11 -> I | C49: =Inputs!C11 -> 23 | D49: =Inputs!F11 -> 14 | E49: =C49-J49+D49 -> 37 | F49: =E49*Inputs!D11*(1+Inputs!E11) -> 8029000 | G49: =MIN(1,MAX(0,Inputs!I11+Inputs!K11*Inputs!$F$44)) -> 0 | H49: =(C49-J49)*G49*Inputs!L11 -> 0 | I49: =D49*Inputs!M11 -> 1400000 | J49: =MAX(0,ROUND(Inputs!N11*(1+Inputs!P11*Inputs!$G$44),0)) -> 0
...
