Workbook

Sheet ReadMe
B2: AY 2027-28 Enrollment & Fund What-If Dashboard
B3: Built from your uploaded AY 27-28 financials. All figures in ₹ (INR).
B5: How to use
B6: 1. Go to the Inputs tab. Pick a scenario (Pessimistic / Realistic / Optimistic) in the yellow cell at the top — every other sheet updates instantly.
B7: 2. Every blue number on Inputs is editable — grade-wise new-joiner counts and their per-grade optimistic/pessimistic swing %, contribution % and its swing, fees, expenses, collection efficiency, cost variance, and fund balances.
B8: 3. The Dashboard tab shows the headline P&L, cash flow and fund position for whichever scenario is selected, plus a side-by-side comparison of all three scenarios and a chart.
B9: 4. The Calculations tab is the engine — grade-by-grade math for all three scenarios. You normally won't need to edit it; everything you'd want to change lives on Inputs.
B11: Key modelling choices
B12: - New Joiners are NOT flexed by one blanket %. Each grade has its own pessimistic/optimistic swing, because a big grade (e.g. LKG) and a hard-to-fill grade (e.g. AS, equivalent to Grade 11) don't move the same way even with the same marketing spend. Grade 11 (AS) is deliberately given a smaller optimistic upside and a larger pessimistic downside than Grade 1 (I), per your instruction that AS admissions are harder to secure.
B13: - Returnable Contribution % (existing students, to the corpus/building fund) also gets its own pessimistic/optimistic range per grade, as a +/- percentage-point swing on the realistic %.
B14: - Contributions from existing students, and (optionally) the Advance from new joiners, are treated as a REFUNDABLE LIABILITY — they hit Cash Inflow and the Fund roll-forward, but are excluded from P&L revenue. No interest is accrued on this balance, matching your note that contributions are returnable without interest.
B15: - Whether the Advance from new joiners is returnable or not is a Yes/No toggle on Inputs (default: Yes / returnable) since your brief only confirmed the treatment for existing-student contributions.
... B24: Yellow fill = key scenario / toggle controls

Sheet Inputs
B1: Inputs & Assumptions
B2: Edit any blue cell. Grades are rows, so each grade can have its own new-joiner / contribution swing (no blanket %).
B4: Active Scenario | C4: Realistic | E4: Treat 'Advance per New Joiner' as returnable (liability), not revenue? | J4: Yes
B6: Grade-wise enrollment, fee & contribution assumptions
B7: Grade | C7: Existing Students | D7: Base Fee (₹) | E7: Fee Increase % (reference only) | F7: New Joiners - Realistic | G7: New Joiners Pessimistic Δ% | H7: New Joiners Optimistic Δ% | I7: Contribution % - Realistic (existing students) | J7: Contribution Pessimistic Δ (pp) | K7: Contribution Optimistic Δ (pp) | L7: Contribution per Student (₹) | M7: Advance per New Joiner (₹)
B8: Pre-KG | C8: 0 | F8: 0 | G8: 0 | H8: 0 | J8: 0 | K8: 0
B9: LKG | C9: 4 | D9: 210000 | E9: 0 | F9: 26 | G9: -0.2 | H9: 0.2 | I9: 0 | J9: 0 | K9: 0 | M9: 100000
B10: UKG | C10: 15 | D10: 201000 | E10: 0 | F10: 15 | G10: -0.15 | H10: 0.2 | I10: 0 | J10: 0 | K10: 0 | M10: 100000
B11: I | C11: 23 | D11: 217000 | E11: 0 | F11: 14 | G11: -0.15 | H11: 0.25 | I11: 0 | J11: 0 | K11: 0 | M11: 100000
B12: II | C12: 33 | D12: 217000 | E12: 0.2 | F12: 0 | G12: -0.25 | H12: 0.15 | I12: 0 | J12: 0 | K12: 0 | M12: 100000
B13: III | C13: 34 | D13: 227000 | E13: 0.2 | F13: 0 | G13: -0.25 | H13: 0.15 | I13: 0 | J13: 0 | K13: 0 | M13: 100000
B14: IV | C14: 32 | D14: 232000 | E14: 0.2 | F14: 0 | G14: -0.25 | H14: 0.15 | I14: 0 | J14: 0 | K14: 0 | M14: 100000
B15: V | C15: 31 | D15: 254000 | E15: 0.2 | F15: 1 | G15: -0.25 | H15: 0.15 | I15: 0 | J15: 0 | K15: 0 | M15: 100000
B16: VI | C16: 31 | D16: 270000 | E16: 0.2 | F16: 1 | G16: -0.2 | H16: 0.15 | I16: 0.2 | J16: -0.1 | K16: 0.1 | L16: 200000 | M16: 100000
B17: VII | C17: 27 | D17: 288000 | E17: 0.2 | F17: 3 | G17: -0.2 | H17: 0.15 | I17: 0.2 | J17: -0.1 | K17: 0.1 | L17: 200000 | M17: 100000
B18: VIII | C18: 25 | D18: 304000 | E18: 0.2 | F18: 5 | G18: -0.2 | H18: 0.15 | I18: 0.3 | J18: -0.1 | K18: 0.1 | L18: 200000 | M18: 100000
B19: IX | C19: 26 | D19: 319000 | E19: 0.2 | F19: 4 | G19: -0.2 | H19: 0.1 | I19: 0.3 | J19: -0.1 | K19: 0.1 | L19: 200000 | M19: 100000
B20: X | C20: 30 | D20: 332000 | E20: 0.2 | F20: 0 | G20: 0 | H20: 0 | I20: 0.2 | J20: -0.1 | K20: 0.1 | L20: 200000 | M20: 100000
B21: AS | C21: 26 | D21: 294000 | E21: 0.2 | F21: 34 | G21: -0.25 | H21: 0.15 | I21: 0.1 | J21: -0.1 | K21: 0.1 | L21: 200000 | M21: 100000
B22: A2 | C22: 29 | D22: 306000 | E22: 0.2 | F22: 1 | G22: -0.15 | H22: 0.1 | I22: 0 | J22: 0 | K22: 0 | M22: 100000
B23: Total | C23: =SUM(C8:C22) -> 366 | E23: =SUM(E8:E22) -> 2.2 | F23: =SUM(F8:F22) -> 104
B25: Annual operating expenses (AY 2027-28 budget)
B26: Expense item | C26: Annual Amount (₹)
B27: Teacher salaries | C27: 57969300
B28: Rent | C28: 2750000
B29: Other core operating expenses | C29: 24347100
B30: Cambridge affiliation | C30: 1069196
B31: Safety / essential maintenance | C31: 2500000
B32: Property purchase loan servicing | C32: 13045454
B33: Growth marketing | C33: 5000000
B34: Additional / discretionary maintenance | C34: 2500000
B35: International obligations | C35: 4200000
B36: Miscellaneous Expenses | C36: =11338105/3 -> 3779368.3
B37: Total Operating Expenses | C37: =SUM(C27:C36) -> 1.1716042e+08
B39: Scenario overlays
B40: Scenario | C40: Fee Collection Efficiency % | D40: Cost Variance % (vs. budget)
B41: Pessimistic | C41: 0.8 | D41: 0.03
B42: Realistic | C42: 0.85 | D42: 0
B43: Optimistic | C43: 0.98 | D43: -0.02
B45: Returnable fund (corpus) balances
...

Sheet Dashboard
B1: AY 2027-28 What-If Dashboard
B2: Enrollment, returnable contributions, cash flow & P&L — scenario planning
B4: Active Scenario: | C4: =Inputs!$C$4 -> Realistic | E4: (change it on the Inputs tab — every number below updates)
B6: Total Cash Inflow | E6: Total Cash Outflow | H6: Net Cash Flow | K6: P&L Net Surplus / (Deficit) | N6: Returnable Fund — Closing Balance
B7: =CHOOSE(MATCH(Inputs!$C$4,{"Pessimistic","Realistic","Optimistic"},0),Calculations!C73,Calculations!D73,Calculations!E73) -> 122509000 | E7: =CHOOSE(MATCH(Inputs!$C$4,{"Pessimistic","Realistic","Optimistic"},0),Calculations!C77,Calculations!D77,Calculations!E77) -> 1.1716042e+08 | H7: =CHOOSE(MATCH(Inputs!$C$4,{"Pessimistic","Realistic","Optimistic"},0),Calculations!C78,Calculations!D78,Calculations!E78) -> 5348581.7 | K7: =CHOOSE(MATCH(Inputs!$C$4,{"Pessimistic","Realistic","Optimistic"},0),Calculations!C84,Calculations!D84,Calculations!E84) -> 6379581.7 | N7: =CHOOSE(MATCH(Inputs!$C$4,{"Pessimistic","Realistic","Optimistic"},0),Calculations!C89,Calculations!D89,Calculations!E89) -> 17500000
B11: Scenario Comparison — P&L & Cash Flow
B12: Metric | C12: Pessimistic | D12: Realistic | E12: Optimistic
B13: New Joiners (count) | C13: =Calculations!C66 -> 84 | D13: =Calculations!D66 -> 104 | E13: =Calculations!E66 -> 122
B14: Total Students | C14: =Calculations!C67 -> 450 | D14: =Calculations!D67 -> 470 | E14: =Calculations!E67 -> 488
B15: Tuition Fee Revenue (₹, accrual) | C15: =Calculations!C68 -> 118391000 | D15: =Calculations!D68 -> 123540000 | E15: =Calculations!E68 -> 127835000
B16: Tuition Fee Cash Collected (₹) | C16: =Calculations!C70 -> 94712800 | D16: =Calculations!D70 -> 105009000 | E16: =Calculations!E70 -> 125278300
B17: Returnable Contribution Collected (₹) | C17: =Calculations!C71 -> 3800000 | D17: =Calculations!D71 -> 7100000 | E17: =Calculations!E71 -> 10400000
B18: Advance from New Joiners Collected (₹) | C18: =Calculations!C72 -> 8400000 | D18: =Calculations!D72 -> 10400000 | E18: =Calculations!E72 -> 12200000
B19: Total Cash Inflow (₹) | C19: =Calculations!C73 -> 106912800 | D19: =Calculations!D73 -> 122509000 | E19: =Calculations!E73 -> 147878300
B20: Total Cash Outflow (₹) | C20: =Calculations!C77 -> 1.2067523e+08 | D20: =Calculations!D77 -> 1.1716042e+08 | E20: =Calculations!E77 -> 1.1481721e+08
B21: Net Cash Flow (₹) | C21: =Calculations!C78 -> -13762431 | D21: =Calculations!D78 -> 5348581.7 | E21: =Calculations!E78 -> 33061090
B22: P&L Total Revenue (₹) | C22: =Calculations!C82 -> 118391000 | D22: =Calculations!D82 -> 123540000 | E22: =Calculations!E82 -> 127835000
B23: P&L Total Operating Expenses (₹) | C23: =Calculations!C83 -> 1.2067523e+08 | D23: =Calculations!D83 -> 1.1716042e+08 | E23: =Calculations!E83 -> 1.1481721e+08
B24: P&L Net Surplus / (Deficit) (₹) | C24: =Calculations!C84 -> -2284230.9 | D24: =Calculations!D84 -> 6379581.7 | E24: =Calculations!E84 -> 13017790
B25: Returnable Fund — Closing Balance (₹) | C25: =Calculations!C89 -> 12200000 | D25: =Calculations!D89 -> 17500000 | E25: =Calculations!E89 -> 22600000
B28: Grade-wise Detail — Active Scenario
B29: Grade | C29: Existing Students | D29: New Joiners | E29: Total Students | F29: Tuition Fee Revenue (₹) | G29: Contribution % | H29: Contribution Collected (₹) | I29: Advance Collected (₹)
B30: =CHOOSE(MATCH(Inputs!$C$4,{"Pessimistic","Realistic","Optimistic"},0),Calculations!B6,Calculations!B26,Calculations!B46) -> Pre-KG | C30: =CHOOSE(MATCH(Inputs!$C$4,{"Pessimistic","Realistic","Optimistic"},0),Calculations!C6,Calculations!C26,Calculations!C46) -> 0 | D30: =CHOOSE(MATCH(Inputs!$C$4,{"Pessimistic","Realistic","Optimistic"},0),Calculations!D6,Calculations!D26,Calculations!D46) -> 0 | E30: =CHOOSE(MATCH(Inputs!$C$4,{"Pessimistic","Realistic","Optimistic"},0),Calculations!E6,Calculations!E26,Calculations!E46) -> 0 | F30: =CHOOSE(MATCH(Inputs!$C$4,{"Pessimistic","Realistic","Optimistic"},0),Calculations!F6,Calculations!F26,Calculations!F46) -> 0 | G30: =CHOOSE(MATCH(Inputs!$C$4,{"Pessimistic","Realistic","Optimistic"},0),Calculations!G6,Calculations!G26,Calculations!G46) -> 0 | H30: =CHOOSE(MATCH(Inputs!$C$4,{"Pessimistic","Realistic","Optimistic"},0),Calculations!H6,Calculations!H26,Calculations!H46) -> 0 | I30: =CHOOSE(MATCH(Inputs!$C$4,{"Pessimistic","Realistic","Optimistic"},0),Calculations!I6,Calculations!I26,Calculations!I46) -> 0
B31: =CHOOSE(MATCH(Inputs!$C$4,{"Pessimistic","Realistic","Optimistic"},0),Calculations!B7,Calculations!B27,Calculations!B47) -> LKG | C31: =CHOOSE(MATCH(Inputs!$C$4,{"Pessimistic","Realistic","Optimistic"},0),Calculations!C7,Calculations!C27,Calculations!C47) -> 4 | D31: =CHOOSE(MATCH(Inputs!$C$4,{"Pessimistic","Realistic","Optimistic"},0),Calculations!D7,Calculations!D27,Calculations!D47) -> 26 | E31: =CHOOSE(MATCH(Inputs!$C$4,{"Pessimistic","Realistic","Optimistic"},0),Calculations!E7,Calculations!E27,Calculations!E47) -> 30 | F31: =CHOOSE(MATCH(Inputs!$C$4,{"Pessimistic","Realistic","Optimistic"},0),Calculations!F7,Calculations!F27,Calculations!F47) -> 6300000 | G31: =CHOOSE(MATCH(Inputs!$C$4,{"Pessimistic","Realistic","Optimistic"},0),Calculations!G7,Calculations!G27,Calculations!G47) -> 0 | H31: =CHOOSE(MATCH(Inputs!$C$4,{"Pessimistic","Realistic","Optimistic"},0),Calculations!H7,Calculations!H27,Calculations!H47) -> 0 | I31: =CHOOSE(MATCH(Inputs!$C$4,{"Pessimistic","Realistic","Optimistic"},0),Calculations!I7,Calculations!I27,Calculations!I47) -> 2600000
B32: =CHOOSE(MATCH(Inputs!$C$4,{"Pessimistic","Realistic","Optimistic"},0),Calculations!B8,Calculations!B28,Calculations!B48) -> UKG | C32: =CHOOSE(MATCH(Inputs!$C$4,{"Pessimistic","Realistic","Optimistic"},0),Calculations!C8,Calculations!C28,Calculations!C48) -> 15 | D32: =CHOOSE(MATCH(Inputs!$C$4,{"Pessimistic","Realistic","Optimistic"},0),Calculations!D8,Calculations!D28,Calculations!D48) -> 15 | E32: =CHOOSE(MATCH(Inputs!$C$4,{"Pessimistic","Realistic","Optimistic"},0),Calculations!E8,Calculations!E28,Calculations!E48) -> 30 | F32: =CHOOSE(MATCH(Inputs!$C$4,{"Pessimistic","Realistic","Optimistic"},0),Calculations!F8,Calculations!F28,Calculations!F48) -> 6030000 | G32: =CHOOSE(MATCH(Inputs!$C$4,{"Pessimistic","Realistic","Optimistic"},0),Calculations!G8,Calculations!G28,Calculations!G48) -> 0 | H32: =CHOOSE(MATCH(Inputs!$C$4,{"Pessimistic","Realistic","Optimistic"},0),Calculations!H8,Calculations!H28,Calculations!H48) -> 0 | I32: =CHOOSE(MATCH(Inputs!$C$4,{"Pessimistic","Realistic","Optimistic"},0),Calculations!I8,Calculations!I28,Calculations!I48) -> 1500000
B33: =CHOOSE(MATCH(Inputs!$C$4,{"Pessimistic","Realistic","Optimistic"},0),Calculations!B9,Calculations!B29,Calculations!B49) -> I | C33: =CHOOSE(MATCH(Inputs!$C$4,{"Pessimistic","Realistic","Optimistic"},0),Calculations!C9,Calculations!C29,Calculations!C49) -> 23 | D33: =CHOOSE(MATCH(Inputs!$C$4,{"Pessimistic","Realistic","Optimistic"},0),Calculations!D9,Calculations!D29,Calculations!D49) -> 14 | E33: =CHOOSE(MATCH(Inputs!$C$4,{"Pessimistic","Realistic","Optimistic"},0),Calculations!E9,Calculations!E29,Calculations!E49) -> 37 | F33: =CHOOSE(MATCH(Inputs!$C$4,{"Pessimistic","Realistic","Optimistic"},0),Calculations!F9,Calculations!F29,Calculations!F49) -> 8029000 | G33: =CHOOSE(MATCH(Inputs!$C$4,{"Pessimistic","Realistic","Optimistic"},0),Calculations!G9,Calculations!G29,Calculations!G49) -> 0 | H33: =CHOOSE(MATCH(Inputs!$C$4,{"Pessimistic","Realistic","Optimistic"},0),Calculations!H9,Calculations!H29,Calculations!H49) -> 0 | I33: =CHOOSE(MATCH(Inputs!$C$4,{"Pessimistic","Realistic","Optimistic"},0),Calculations!I9,Calculations!I29,Calculations!I49) -> 1400000
B34: =CHOOSE(MATCH(Inputs!$C$4,{"Pessimistic","Realistic","Optimistic"},0),Calculations!B10,Calculations!B30,Calculations!B50) -> II | C34: =CHOOSE(MATCH(Inputs!$C$4,{"Pessimistic","Realistic","Optimistic"},0),Calculations!C10,Calculations!C30,Calculations!C50) -> 33 | D34: =CHOOSE(MATCH(Inputs!$C$4,{"Pessimistic","Realistic","Optimistic"},0),Calculations!D10,Calculations!D30,Calculations!D50) -> 0 | E34: =CHOOSE(MATCH(Inputs!$C$4,{"Pessimistic","Realistic","Optimistic"},0),Calculations!E10,Calculations!E30,Calculations!E50) -> 33 | F34: =CHOOSE(MATCH(Inputs!$C$4,{"Pessimistic","Realistic","Optimistic"},0),Calculations!F10,Calculations!F30,Calculations!F50) -> 7161000 | G34: =CHOOSE(MATCH(Inputs!$C$4,{"Pessimistic","Realistic","Optimistic"},0),Calculations!G10,Calculations!G30,Calculations!G50) -> 0 | H34: =CHOOSE(MATCH(Inputs!$C$4,{"Pessimistic","Realistic","Optimistic"},0),Calculations!H10,Calculations!H30,Calculations!H50) -> 0 | I34: =CHOOSE(MATCH(Inputs!$C$4,{"Pessimistic","Realistic","Optimistic"},0),Calculations!I10,Calculations!I30,Calculations!I50) -> 0
B35: =CHOOSE(MATCH(Inputs!$C$4,{"Pessimistic","Realistic","Optimistic"},0),Calculations!B11,Calculations!B31,Calculations!B51) -> III | C35: =CHOOSE(MATCH(Inputs!$C$4,{"Pessimistic","Realistic","Optimistic"},0),Calculations!C11,Calculations!C31,Calculations!C51) -> 34 | D35: =CHOOSE(MATCH(Inputs!$C$4,{"Pessimistic","Realistic","Optimistic"},0),Calculations!D11,Calculations!D31,Calculations!D51) -> 0 | E35: =CHOOSE(MATCH(Inputs!$C$4,{"Pessimistic","Realistic","Optimistic"},0),Calculations!E11,Calculations!E31,Calculations!E51) -> 34 | F35: =CHOOSE(MATCH(Inputs!$C$4,{"Pessimistic","Realistic","Optimistic"},0),Calculations!F11,Calculations!F31,Calculations!F51) -> 7718000 | G35: =CHOOSE(MATCH(Inputs!$C$4,{"Pessimistic","Realistic","Optimistic"},0),Calculations!G11,Calculations!G31,Calculations!G51) -> 0 | H35: =CHOOSE(MATCH(Inputs!$C$4,{"Pessimistic","Realistic","Optimistic"},0),Calculations!H11,Calculations!H31,Calculations!H51) -> 0 | I35: =CHOOSE(MATCH(Inputs!$C$4,{"Pessimistic","Realistic","Optimistic"},0),Calculations!I11,Calculations!I31,Calculations!I51) -> 0
B36: =CHOOSE(MATCH(Inputs!$C$4,{"Pessimistic","Realistic","Optimistic"},0),Calculations!B12,Calculations!B32,Calculations!B52) -> IV | C36: =CHOOSE(MATCH(Inputs!$C$4,{"Pessimistic","Realistic","Optimistic"},0),Calculations!C12,Calculations!C32,Calculations!C52) -> 32 | D36: =CHOOSE(MATCH(Inputs!$C$4,{"Pessimistic","Realistic","Optimistic"},0),Calculations!D12,Calculations!D32,Calculations!D52) -> 0 | E36: =CHOOSE(MATCH(Inputs!$C$4,{"Pessimistic","Realistic","Optimistic"},0),Calculations!E12,Calculations!E32,Calculations!E52) -> 32 | F36: =CHOOSE(MATCH(Inputs!$C$4,{"Pessimistic","Realistic","Optimistic"},0),Calculations!F12,Calculations!F32,Calculations!F52) -> 7424000 | G36: =CHOOSE(MATCH(Inputs!$C$4,{"Pessimistic","Realistic","Optimistic"},0),Calculations!G12,Calculations!G32,Calculations!G52) -> 0 | H36: =CHOOSE(MATCH(Inputs!$C$4,{"Pessimistic","Realistic","Optimistic"},0),Calculations!H12,Calculations!H32,Calculations!H52) -> 0 | I36: =CHOOSE(MATCH(Inputs!$C$4,{"Pessimistic","Realistic","Optimistic"},0),Calculations!I12,Calculations!I32,Calculations!I52) -> 0
B37: =CHOOSE(MATCH(Inputs!$C$4,{"Pessimistic","Realistic","Optimistic"},0),Calculations!B13,Calculations!B33,Calculations!B53) -> V | C37: =CHOOSE(MATCH(Inputs!$C$4,{"Pessimistic","Realistic","Optimistic"},0),Calculations!C13,Calculations!C33,Calculations!C53) -> 31 | D37: =CHOOSE(MATCH(Inputs!$C$4,{"Pessimistic","Realistic","Optimistic"},0),Calculations!D13,Calculations!D33,Calculations!D53) -> 1 | E37: =CHOOSE(MATCH(Inputs!$C$4,{"Pessimistic","Realistic","Optimistic"},0),Calculations!E13,Calculations!E33,Calculations!E53) -> 32 | F37: =CHOOSE(MATCH(Inputs!$C$4,{"Pessimistic","Realistic","Optimistic"},0),Calculations!F13,Calculations!F33,Calculations!F53) -> 8128000 | G37: =CHOOSE(MATCH(Inputs!$C$4,{"Pessimistic","Realistic","Optimistic"},0),Calculations!G13,Calculations!G33,Calculations!G53) -> 0 | H37: =CHOOSE(MATCH(Inputs!$C$4,{"Pessimistic","Realistic","Optimistic"},0),Calculations!H13,Calculations!H33,Calculations!H53) -> 0 | I37: =CHOOSE(MATCH(Inputs!$C$4,{"Pessimistic","Realistic","Optimistic"},0),Calculations!I13,Calculations!I33,Calculations!I53) -> 100000
B38: =CHOOSE(MATCH(Inputs!$C$4,{"Pessimistic","Realistic","Optimistic"},0),Calculations!B14,Calculations!B34,Calculations!B54) -> VI | C38: =CHOOSE(MATCH(Inputs!$C$4,{"Pessimistic","Realistic","Optimistic"},0),Calculations!C14,Calculations!C34,Calculations!C54) -> 31 | D38: =CHOOSE(MATCH(Inputs!$C$4,{"Pessimistic","Realistic","Optimistic"},0),Calculations!D14,Calculations!D34,Calculations!D54) -> 1 | E38: =CHOOSE(MATCH(Inputs!$C$4,{"Pessimistic","Realistic","Optimistic"},0),Calculations!E14,Calculations!E34,Calculations!E54) -> 32 | F38: =CHOOSE(MATCH(Inputs!$C$4,{"Pessimistic","Realistic","Optimistic"},0),Calculations!F14,Calculations!F34,Calculations!F54) -> 8640000 | G38: =CHOOSE(MATCH(Inputs!$C$4,{"Pessimistic","Realistic","Optimistic"},0),Calculations!G14,Calculations!G34,Calculations!G54) -> 0.2 | H38: =CHOOSE(MATCH(Inputs!$C$4,{"Pessimistic","Realistic","Optimistic"},0),Calculations!H14,Calculations!H34,Calculations!H54) -> 1240000 | I38: =CHOOSE(MATCH(Inputs!$C$4,{"Pessimistic","Realistic","Optimistic"},0),Calculations!I14,Calculations!I34,Calculations!I54) -> 100000
B39: =CHOOSE(MATCH(Inputs!$C$4,{"Pessimistic","Realistic","Optimistic"},0),Calculations!B15,Calculations!B35,Calculations!B55) -> VII | C39: =CHOOSE(MATCH(Inputs!$C$4,{"Pessimistic","Realistic","Optimistic"},0),Calculations!C15,Calculations!C35,Calculations!C55) -> 27 | D39: =CHOOSE(MATCH(Inputs!$C$4,{"Pessimistic","Realistic","Optimistic"},0),Calculations!D15,Calculations!D35,Calculations!D55) -> 3 | E39: =CHOOSE(MATCH(Inputs!$C$4,{"Pessimistic","Realistic","Optimistic"},0),Calculations!E15,Calculations!E35,Calculations!E55) -> 30 | F39: =CHOOSE(MATCH(Inputs!$C$4,{"Pessimistic","Realistic","Optimistic"},0),Calculations!F15,Calculations!F35,Calculations!F55) -> 8640000 | G39: =CHOOSE(MATCH(Inputs!$C$4,{"Pessimistic","Realistic","Optimistic"},0),Calculations!G15,Calculations!G35,Calculations!G55) -> 0.2 | H39: =CHOOSE(MATCH(Inputs!$C$4,{"Pessimistic","Realistic","Optimistic"},0),Calculations!H15,Calculations!H35,Calculations!H55) -> 1080000 | I39: =CHOOSE(MATCH(Inputs!$C$4,{"Pessimistic","Realistic","Optimistic"},0),Calculations!I15,Calculations!I35,Calculations!I55) -> 300000
B40: =CHOOSE(MATCH(Inputs!$C$4,{"Pessimistic","Realistic","Optimistic"},0),Calculations!B16,Calculations!B36,Calculations!B56) -> VIII | C40: =CHOOSE(MATCH(Inputs!$C$4,{"Pessimistic","Realistic","Optimistic"},0),Calculations!C16,Calculations!C36,Calculations!C56) -> 25 | D40: =CHOOSE(MATCH(Inputs!$C$4,{"Pessimistic","Realistic","Optimistic"},0),Calculations!D16,Calculations!D36,Calculations!D56) -> 5 | E40: =CHOOSE(MATCH(Inputs!$C$4,{"Pessimistic","Realistic","Optimistic"},0),Calculations!E16,Calculations!E36,Calculations!E56) -> 30 | F40: =CHOOSE(MATCH(Inputs!$C$4,{"Pessimistic","Realistic","Optimistic"},0),Calculations!F16,Calculations!F36,Calculations!F56) -> 9120000 | G40: =CHOOSE(MATCH(Inputs!$C$4,{"Pessimistic","Realistic","Optimistic"},0),Calculations!G16,Calculations!G36,Calculations!G56) -> 0.3 | H40: =CHOOSE(MATCH(Inputs!$C$4,{"Pessimistic","Realistic","Optimistic"},0),Calculations!H16,Calculations!H36,Calculations!H56) -> 1500000 | I40: =CHOOSE(MATCH(Inputs!$C$4,{"Pessimistic","Realistic","Optimistic"},0),Calculations!I16,Calculations!I36,Calculations!I56) -> 500000
B41: =CHOOSE(MATCH(Inputs!$C$4,{"Pessimistic","Realistic","Optimistic"},0),Calculations!B17,Calculations!B37,Calculations!B57) -> IX | C41: =CHOOSE(MATCH(Inputs!$C$4,{"Pessimistic","Realistic","Optimistic"},0),Calculations!C17,Calculations!C37,Calculations!C57) -> 26 | D41: =CHOOSE(MATCH(Inputs!$C$4,{"Pessimistic","Realistic","Optimistic"},0),Calculations!D17,Calculations!D37,Calculations!D57) -> 4 | E41: =CHOOSE(MATCH(Inputs!$C$4,{"Pessimistic","Realistic","Optimistic"},0),Calculations!E17,Calculations!E37,Calculations!E57) -> 30 | F41: =CHOOSE(MATCH(Inputs!$C$4,{"Pessimistic","Realistic","Optimistic"},0),Calculations!F17,Calculations!F37,Calculations!F57) -> 9570000 | G41: =CHOOSE(MATCH(Inputs!$C$4,{"Pessimistic","Realistic","Optimistic"},0),Calculations!G17,Calculations!G37,Calculations!G57) -> 0.3 | H41: =CHOOSE(MATCH(Inputs!$C$4,{"Pessimistic","Realistic","Optimistic"},0),Calculations!H17,Calculations!H37,Calculations!H57) -> 1560000 | I41: =CHOOSE(MATCH(Inputs!$C$4,{"Pessimistic","Realistic","Optimistic"},0),Calculations!I17,Calculations!I37,Calculations!I57) -> 400000
... B44: =CHOOSE(MATCH(Inputs!$C$4,{"Pessimistic","Realistic","Optimistic"},0),Calculations!B20,Calculations!B40,Calculations!B60) -> A2 | C44: =CHOOSE(MATCH(Inputs!$C$4,{"Pessimistic","Realistic","Optimistic"},0),Calculations!C20,Calculations!C40,Calculations!C60) -> 29 | D44: =CHOOSE(MATCH(Inputs!$C$4,{"Pessimistic","Realistic","Optimistic"},0),Calculations!D20,Calculations!D40,Calculations!D60) -> 1 | E44: =CHOOSE(MATCH(Inputs!$C$4,{"Pessimistic","Realistic","Optimistic"},0),Calculations!E20,Calculations!E40,Calculations!E60) -> 30 | F44: =CHOOSE(MATCH(Inputs!$C$4,{"Pessimistic","Realistic","Optimistic"},0),Calculations!F20,Calculations!F40,Calculations!F60) -> 9180000 | G44: =CHOOSE(MATCH(Inputs!$C$4,{"Pessimistic","Realistic","Optimistic"},0),Calculations!G20,Calculations!G40,Calculations!G60) -> 0 | H44: =CHOOSE(MATCH(Inputs!$C$4,{"Pessimistic","Realistic","Optimistic"},0),Calculations!H20,Calculations!H40,Calculations!H60) -> 0 | I44: =CHOOSE(MATCH(Inputs!$C$4,{"Pessimistic","Realistic","Optimistic"},0),Calculations!I20,Calculations!I40,Calculations!I60) -> 100000
B45: Total | C45: =SUM(C30:C44) -> 366 | D45: =SUM(D30:D44) -> 104 | E45: =SUM(E30:E44) -> 470 | F45: =SUM(F30:F44) -> 123540000 | H45: =SUM(H30:H44) -> 7100000 | I45: =SUM(I30:I44) -> 10400000

Sheet Calculations
B1: Calculations — Scenario Engine
B2: Grade-by-grade math for each scenario. Everything here is a formula pulling from Inputs — normally no need to edit.
B4: PESSIMISTIC SCENARIO
B5: Grade | C5: Existing Students | D5: New Joiners | E5: Total Students | F5: Tuition Fee Revenue (₹) | G5: Contribution % | H5: Contribution Collected (₹) | I5: Advance Collected (₹)
B6: =Inputs!B8 -> Pre-KG | C6: =Inputs!C8 -> 0 | D6: =MAX(0,ROUND(Inputs!F8*(1+Inputs!G8),0)) -> 0 | E6: =C6+D6 -> 0 | F6: =E6*Inputs!D8 -> 0 | G6: =MIN(1,MAX(0,Inputs!I8+Inputs!J8)) -> 0 | H6: =C6*G6*Inputs!L8 -> 0 | I6: =D6*Inputs!M8 -> 0
B7: =Inputs!B9 -> LKG | C7: =Inputs!C9 -> 4 | D7: =MAX(0,ROUND(Inputs!F9*(1+Inputs!G9),0)) -> 21 | E7: =C7+D7 -> 25 | F7: =E7*Inputs!D9 -> 5250000 | G7: =MIN(1,MAX(0,Inputs!I9+Inputs!J9)) -> 0 | H7: =C7*G7*Inputs!L9 -> 0 | I7: =D7*Inputs!M9 -> 2100000
B8: =Inputs!B10 -> UKG | C8: =Inputs!C10 -> 15 | D8: =MAX(0,ROUND(Inputs!F10*(1+Inputs!G10),0)) -> 13 | E8: =C8+D8 -> 28 | F8: =E8*Inputs!D10 -> 5628000 | G8: =MIN(1,MAX(0,Inputs!I10+Inputs!J10)) -> 0 | H8: =C8*G8*Inputs!L10 -> 0 | I8: =D8*Inputs!M10 -> 1300000
B9: =Inputs!B11 -> I | C9: =Inputs!C11 -> 23 | D9: =MAX(0,ROUND(Inputs!F11*(1+Inputs!G11),0)) -> 12 | E9: =C9+D9 -> 35 | F9: =E9*Inputs!D11 -> 7595000 | G9: =MIN(1,MAX(0,Inputs!I11+Inputs!J11)) -> 0 | H9: =C9*G9*Inputs!L11 -> 0 | I9: =D9*Inputs!M11 -> 1200000
B10: =Inputs!B12 -> II | C10: =Inputs!C12 -> 33 | D10: =MAX(0,ROUND(Inputs!F12*(1+Inputs!G12),0)) -> 0 | E10: =C10+D10 -> 33 | F10: =E10*Inputs!D12 -> 7161000 | G10: =MIN(1,MAX(0,Inputs!I12+Inputs!J12)) -> 0 | H10: =C10*G10*Inputs!L12 -> 0 | I10: =D10*Inputs!M12 -> 0
B11: =Inputs!B13 -> III | C11: =Inputs!C13 -> 34 | D11: =MAX(0,ROUND(Inputs!F13*(1+Inputs!G13),0)) -> 0 | E11: =C11+D11 -> 34 | F11: =E11*Inputs!D13 -> 7718000 | G11: =MIN(1,MAX(0,Inputs!I13+Inputs!J13)) -> 0 | H11: =C11*G11*Inputs!L13 -> 0 | I11: =D11*Inputs!M13 -> 0
B12: =Inputs!B14 -> IV | C12: =Inputs!C14 -> 32 | D12: =MAX(0,ROUND(Inputs!F14*(1+Inputs!G14),0)) -> 0 | E12: =C12+D12 -> 32 | F12: =E12*Inputs!D14 -> 7424000 | G12: =MIN(1,MAX(0,Inputs!I14+Inputs!J14)) -> 0 | H12: =C12*G12*Inputs!L14 -> 0 | I12: =D12*Inputs!M14 -> 0
B13: =Inputs!B15 -> V | C13: =Inputs!C15 -> 31 | D13: =MAX(0,ROUND(Inputs!F15*(1+Inputs!G15),0)) -> 1 | E13: =C13+D13 -> 32 | F13: =E13*Inputs!D15 -> 8128000 | G13: =MIN(1,MAX(0,Inputs!I15+Inputs!J15)) -> 0 | H13: =C13*G13*Inputs!L15 -> 0 | I13: =D13*Inputs!M15 -> 100000
B14: =Inputs!B16 -> VI | C14: =Inputs!C16 -> 31 | D14: =MAX(0,ROUND(Inputs!F16*(1+Inputs!G16),0)) -> 1 | E14: =C14+D14 -> 32 | F14: =E14*Inputs!D16 -> 8640000 | G14: =MIN(1,MAX(0,Inputs!I16+Inputs!J16)) -> 0.1 | H14: =C14*G14*Inputs!L16 -> 620000 | I14: =D14*Inputs!M16 -> 100000
B15: =Inputs!B17 -> VII | C15: =Inputs!C17 -> 27 | D15: =MAX(0,ROUND(Inputs!F17*(1+Inputs!G17),0)) -> 2 | E15: =C15+D15 -> 29 | F15: =E15*Inputs!D17 -> 8352000 | G15: =MIN(1,MAX(0,Inputs!I17+Inputs!J17)) -> 0.1 | H15: =C15*G15*Inputs!L17 -> 540000 | I15: =D15*Inputs!M17 -> 200000
B16: =Inputs!B18 -> VIII | C16: =Inputs!C18 -> 25 | D16: =MAX(0,ROUND(Inputs!F18*(1+Inputs!G18),0)) -> 4 | E16: =C16+D16 -> 29 | F16: =E16*Inputs!D18 -> 8816000 | G16: =MIN(1,MAX(0,Inputs!I18+Inputs!J18)) -> 0.2 | H16: =C16*G16*Inputs!L18 -> 1000000 | I16: =D16*Inputs!M18 -> 400000
B17: =Inputs!B19 -> IX | C17: =Inputs!C19 -> 26 | D17: =MAX(0,ROUND(Inputs!F19*(1+Inputs!G19),0)) -> 3 | E17: =C17+D17 -> 29 | F17: =E17*Inputs!D19 -> 9251000 | G17: =MIN(1,MAX(0,Inputs!I19+Inputs!J19)) -> 0.2 | H17: =C17*G17*Inputs!L19 -> 1040000 | I17: =D17*Inputs!M19 -> 300000
... B20: =Inputs!B22 -> A2 | C20: =Inputs!C22 -> 29 | D20: =MAX(0,ROUND(Inputs!F22*(1+Inputs!G22),0)) -> 1 | E20: =C20+D20 -> 30 | F20: =E20*Inputs!D22 -> 9180000 | G20: =MIN(1,MAX(0,Inputs!I22+Inputs!J22)) -> 0 | H20: =C20*G20*Inputs!L22 -> 0 | I20: =D20*Inputs!M22 -> 100000
B21: Total | C21: =SUM(C6:C20) -> 366 | D21: =SUM(D6:D20) -> 84 | E21: =SUM(E6:E20) -> 450 | F21: =SUM(F6:F20) -> 118391000 | H21: =SUM(H6:H20) -> 3800000 | I21: =SUM(I6:I20) -> 8400000
B24: REALISTIC SCENARIO
B25: Grade | C25: Existing Students | D25: New Joiners | E25: Total Students | F25: Tuition Fee Revenue (₹) | G25: Contribution % | H25: Contribution Collected (₹) | I25: Advance Collected (₹)
B26: =Inputs!B8 -> Pre-KG | C26: =Inputs!C8 -> 0 | D26: =Inputs!F8 -> 0 | E26: =C26+D26 -> 0 | F26: =E26*Inputs!D8 -> 0 | G26: =Inputs!I8 -> 0 | H26: =C26*G26*Inputs!L8 -> 0 | I26: =D26*Inputs!M8 -> 0
B27: =Inputs!B9 -> LKG | C27: =Inputs!C9 -> 4 | D27: =Inputs!F9 -> 26 | E27: =C27+D27 -> 30 | F27: =E27*Inputs!D9 -> 6300000 | G27: =Inputs!I9 -> 0 | H27: =C27*G27*Inputs!L9 -> 0 | I27: =D27*Inputs!M9 -> 2600000
B28: =Inputs!B10 -> UKG | C28: =Inputs!C10 -> 15 | D28: =Inputs!F10 -> 15 | E28: =C28+D28 -> 30 | F28: =E28*Inputs!D10 -> 6030000 | G28: =Inputs!I10 -> 0 | H28: =C28*G28*Inputs!L10 -> 0 | I28: =D28*Inputs!M10 -> 1500000
B29: =Inputs!B11 -> I | C29: =Inputs!C11 -> 23 | D29: =Inputs!F11 -> 14 | E29: =C29+D29 -> 37 | F29: =E29*Inputs!D11 -> 8029000 | G29: =Inputs!I11 -> 0 | H29: =C29*G29*Inputs!L11 -> 0 | I29: =D29*Inputs!M11 -> 1400000
B30: =Inputs!B12 -> II | C30: =Inputs!C12 -> 33 | D30: =Inputs!F12 -> 0 | E30: =C30+D30 -> 33 | F30: =E30*Inputs!D12 -> 7161000 | G30: =Inputs!I12 -> 0 | H30: =C30*G30*Inputs!L12 -> 0 | I30: =D30*Inputs!M12 -> 0
B31: =Inputs!B13 -> III | C31: =Inputs!C13 -> 34 | D31: =Inputs!F13 -> 0 | E31: =C31+D31 -> 34 | F31: =E31*Inputs!D13 -> 7718000 | G31: =Inputs!I13 -> 0 | H31: =C31*G31*Inputs!L13 -> 0 | I31: =D31*Inputs!M13 -> 0
B32: =Inputs!B14 -> IV | C32: =Inputs!C14 -> 32 | D32: =Inputs!F14 -> 0 | E32: =C32+D32 -> 32 | F32: =E32*Inputs!D14 -> 7424000 | G32: =Inputs!I14 -> 0 | H32: =C32*G32*Inputs!L14 -> 0 | I32: =D32*Inputs!M14 -> 0
B33: =Inputs!B15 -> V | C33: =Inputs!C15 -> 31 | D33: =Inputs!F15 -> 1 | E33: =C33+D33 -> 32 | F33: =E33*Inputs!D15 -> 8128000 | G33: =Inputs!I15 -> 0 | H33: =C33*G33*Inputs!L15 -> 0 | I33: =D33*Inputs!M15 -> 100000
B34: =Inputs!B16 -> VI | C34: =Inputs!C16 -> 31 | D34: =Inputs!F16 -> 1 | E34: =C34+D34 -> 32 | F34: =E34*Inputs!D16 -> 8640000 | G34: =Inputs!I16 -> 0.2 | H34: =C34*G34*Inputs!L16 -> 1240000 | I34: =D34*Inputs!M16 -> 100000
B35: =Inputs!B17 -> VII | C35: =Inputs!C17 -> 27 | D35: =Inputs!F17 -> 3 | E35: =C35+D35 -> 30 | F35: =E35*Inputs!D17 -> 8640000 | G35: =Inputs!I17 -> 0.2 | H35: =C35*G35*Inputs!L17 -> 1080000 | I35: =D35*Inputs!M17 -> 300000
B36: =Inputs!B18 -> VIII | C36: =Inputs!C18 -> 25 | D36: =Inputs!F18 -> 5 | E36: =C36+D36 -> 30 | F36: =E36*Inputs!D18 -> 9120000 | G36: =Inputs!I18 -> 0.3 | H36: =C36*G36*Inputs!L18 -> 1500000 | I36: =D36*Inputs!M18 -> 500000
B37: =Inputs!B19 -> IX | C37: =Inputs!C19 -> 26 | D37: =Inputs!F19 -> 4 | E37: =C37+D37 -> 30 | F37: =E37*Inputs!D19 -> 9570000 | G37: =Inputs!I19 -> 0.3 | H37: =C37*G37*Inputs!L19 -> 1560000 | I37: =D37*Inputs!M19 -> 400000
... B40: =Inputs!B22 -> A2 | C40: =Inputs!C22 -> 29 | D40: =Inputs!F22 -> 1 | E40: =C40+D40 -> 30 | F40: =E40*Inputs!D22 -> 9180000 | G40: =Inputs!I22 -> 0 | H40: =C40*G40*Inputs!L22 -> 0 | I40: =D40*Inputs!M22 -> 100000
B41: Total | C41: =SUM(C26:C40) -> 366 | D41: =SUM(D26:D40) -> 104 | E41: =SUM(E26:E40) -> 470 | F41: =SUM(F26:F40) -> 123540000 | H41: =SUM(H26:H40) -> 7100000 | I41: =SUM(I26:I40) -> 10400000
B44: OPTIMISTIC SCENARIO
B45: Grade | C45: Existing Students | D45: New Joiners | E45: Total Students | F45: Tuition Fee Revenue (₹) | G45: Contribution % | H45: Contribution Collected (₹) | I45: Advance Collected (₹)
B46: =Inputs!B8 -> Pre-KG | C46: =Inputs!C8 -> 0 | D46: =MAX(0,ROUND(Inputs!F8*(1+Inputs!H8),0)) -> 0 | E46: =C46+D46 -> 0 | F46: =E46*Inputs!D8 -> 0 | G46: =MIN(1,MAX(0,Inputs!I8+Inputs!K8)) -> 0 | H46: =C46*G46*Inputs!L8 -> 0 | I46: =D46*Inputs!M8 -> 0
B47: =Inputs!B9 -> LKG | C47: =Inputs!C9 -> 4 | D47: =MAX(0,ROUND(Inputs!F9*(1+Inputs!H9),0)) -> 31 | E47: =C47+D47 -> 35 | F47: =E47*Inputs!D9 -> 7350000 | G47: =MIN(1,MAX(0,Inputs!I9+Inputs!K9)) -> 0 | H47: =C47*G47*Inputs!L9 -> 0 | I47: =D47*Inputs!M9 -> 3100000
B48: =Inputs!B10 -> UKG | C48: =Inputs!C10 -> 15 | D48: =MAX(0,ROUND(Inputs!F10*(1+Inputs!H10),0)) -> 18 | E48: =C48+D48 -> 33 | F48: =E48*Inputs!D10 -> 6633000 | G48: =MIN(1,MAX(0,Inputs!I10+Inputs!K10)) -> 0 | H48: =C48*G48*Inputs!L10 -> 0 | I48: =D48*Inputs!M10 -> 1800000
B49: =Inputs!B11 -> I | C49: =Inputs!C11 -> 23 | D49: =MAX(0,ROUND(Inputs!F11*(1+Inputs!H11),0)) -> 18 | E49: =C49+D49 -> 41 | F49: =E49*Inputs!D11 -> 8897000 | G49: =MIN(1,MAX(0,Inputs!I11+Inputs!K11)) -> 0 | H49: =C49*G49*Inputs!L11 -> 0 | I49: =D49*Inputs!M11 -> 1800000
...
